[2021-01-06 12:34:33,375] [autoreload.py:617] [autoreload:run_with_reloader] [INFO]- Watching for file changes with StatReloader
[2021-01-06 12:41:57,909] [autoreload.py:617] [autoreload:run_with_reloader] [INFO]- Watching for file changes with StatReloader
[2021-01-06 12:42:31,479] [autoreload.py:617] [autoreload:run_with_reloader] [INFO]- Watching for file changes with StatReloader
[2021-01-06 17:10:38,167] [autoreload.py:617] [autoreload:run_with_reloader] [INFO]- Watching for file changes with StatReloader
[2021-01-06 17:10:41,389] [basehttp.py:157] [basehttp:log_message] [INFO]- "GET / HTTP/1.1" 200 16299
[2021-01-06 17:10:41,459] [basehttp.py:157] [basehttp:log_message] [INFO]- "GET /static/admin/css/fonts.css HTTP/1.1" 304 0
[2021-01-06 17:10:41,574] [basehttp.py:157] [basehttp:log_message] [INFO]- "GET /static/admin/fonts/Roboto-Bold-webfont.woff HTTP/1.1" 304 0
[2021-01-06 17:10:41,575] [basehttp.py:157] [basehttp:log_message] [INFO]- "GET /static/admin/fonts/Roboto-Regular-webfont.woff HTTP/1.1" 304 0
[2021-01-06 17:10:41,575] [basehttp.py:157] [basehttp:log_message] [INFO]- "GET /static/admin/fonts/Roboto-Light-webfont.woff HTTP/1.1" 304 0
[2021-01-06 17:10:41,663] [log.py:224] [log:log_response] [WARNING]- Not Found: /favicon.ico
[2021-01-06 17:10:41,664] [basehttp.py:157] [basehttp:log_message] [WARNING]- "GET /favicon.ico HTTP/1.1" 404 1970
[2021-01-06 18:40:24,895] [autoreload.py:617] [autoreload:run_with_reloader] [INFO]- Watching for file changes with StatReloader
[2021-01-06 18:40:48,092] [autoreload.py:617] [autoreload:run_with_reloader] [INFO]- Watching for file changes with StatReloader
[2021-01-06 18:40:52,874] [log.py:224] [log:log_response] [WARNING]- Not Found: /
[2021-01-06 18:40:52,875] [basehttp.py:157] [basehttp:log_message] [WARNING]- "GET / HTTP/1.1" 404 2024
[2021-01-06 18:41:03,345] [log.py:224] [log:log_response] [WARNING]- Not Found: /user
[2021-01-06 18:41:03,345] [basehttp.py:157] [basehttp:log_message] [WARNING]- "GET /user HTTP/1.1" 404 2054
[2021-01-06 18:41:14,995] [log.py:224] [log:log_response] [WARNING]- Not Found: /user/
[2021-01-06 18:41:14,995] [basehttp.py:157] [basehttp:log_message] [WARNING]- "GET /user/ HTTP/1.1" 404 2106
[2021-01-06 18:41:53,743] [autoreload.py:617] [autoreload:run_with_reloader] [INFO]- Watching for file changes with StatReloader
[2021-01-06 18:41:56,712] [log.py:224] [log:log_response] [WARNING]- Not Found: /user/
[2021-01-06 18:41:56,712] [basehttp.py:157] [basehttp:log_message] [WARNING]- "GET /user/ HTTP/1.1" 404 2106
[2021-01-06 18:41:58,446] [log.py:224] [log:log_response] [WARNING]- Not Found: /user/
[2021-01-06 18:41:58,446] [basehttp.py:157] [basehttp:log_message] [WARNING]- "GET /user/ HTTP/1.1" 404 2106
[2021-01-06 18:43:47,694] [log.py:224] [log:log_response] [WARNING]- Not Found: /user/
[2021-01-06 18:43:47,694] [basehttp.py:157] [basehttp:log_message] [WARNING]- "GET /user/ HTTP/1.1" 404 2106
[2021-01-06 18:43:48,406] [log.py:224] [log:log_response] [WARNING]- Not Found: /user/
[2021-01-06 18:43:48,406] [basehttp.py:157] [basehttp:log_message] [WARNING]- "GET /user/ HTTP/1.1" 404 2106
[2021-01-06 18:43:48,978] [log.py:224] [log:log_response] [WARNING]- Not Found: /user/
[2021-01-06 18:43:48,979] [basehttp.py:157] [basehttp:log_message] [WARNING]- "GET /user/ HTTP/1.1" 404 2106
[2021-01-06 18:43:49,461] [log.py:224] [log:log_response] [WARNING]- Not Found: /user/
[2021-01-06 18:43:49,461] [basehttp.py:157] [basehttp:log_message] [WARNING]- "GET /user/ HTTP/1.1" 404 2106
[2021-01-06 18:43:49,673] [log.py:224] [log:log_response] [WARNING]- Not Found: /user/
[2021-01-06 18:43:49,674] [basehttp.py:157] [basehttp:log_message] [WARNING]- "GET /user/ HTTP/1.1" 404 2106
[2021-01-06 18:43:49,857] [log.py:224] [log:log_response] [WARNING]- Not Found: /user/
[2021-01-06 18:43:49,858] [basehttp.py:157] [basehttp:log_message] [WARNING]- "GET /user/ HTTP/1.1" 404 2106
[2021-01-06 18:43:50,092] [log.py:224] [log:log_response] [WARNING]- Not Found: /user/
[2021-01-06 18:43:50,092] [basehttp.py:157] [basehttp:log_message] [WARNING]- "GET /user/ HTTP/1.1" 404 2106
[2021-01-06 18:44:09,076] [autoreload.py:617] [autoreload:run_with_reloader] [INFO]- Watching for file changes with StatReloader
[2021-01-06 18:44:12,227] [log.py:224] [log:log_response] [WARNING]- Not Found: /user/
[2021-01-06 18:44:12,228] [basehttp.py:157] [basehttp:log_message] [WARNING]- "GET /user/ HTTP/1.1" 404 1952
[2021-01-06 18:44:14,806] [log.py:224] [log:log_response] [WARNING]- Not Found: /
[2021-01-06 18:44:14,807] [basehttp.py:157] [basehttp:log_message] [WARNING]- "GET / HTTP/1.1" 404 2024
[2021-01-06 18:44:35,201] [autoreload.py:617] [autoreload:run_with_reloader] [INFO]- Watching for file changes with StatReloader
[2021-01-06 18:44:37,805] [basehttp.py:157] [basehttp:log_message] [INFO]- "GET / HTTP/1.1" 200 16299
[2021-01-06 18:47:55,321] [autoreload.py:617] [autoreload:run_with_reloader] [INFO]- Watching for file changes with StatReloader
[2021-01-06 18:47:56,917] [basehttp.py:157] [basehttp:log_message] [INFO]- "GET / HTTP/1.1" 200 16299
[2021-01-06 18:50:19,991] [autoreload.py:240] [autoreload:trigger_reload] [INFO]- E:\Python\blog\backend\user\urls.py changed, reloading.
[2021-01-06 18:50:20,728] [autoreload.py:617] [autoreload:run_with_reloader] [INFO]- Watching for file changes with StatReloader
[2021-01-06 18:50:23,092] [basehttp.py:157] [basehttp:log_message] [INFO]- "GET / HTTP/1.1" 200 5256
[2021-01-06 18:50:24,155] [basehttp.py:157] [basehttp:log_message] [INFO]- "GET /static/rest_framework/css/default.css HTTP/1.1" 200 1131
[2021-01-06 18:50:24,157] [basehttp.py:157] [basehttp:log_message] [INFO]- "GET /static/rest_framework/css/bootstrap-tweaks.css HTTP/1.1" 200 3385
[2021-01-06 18:50:24,159] [basehttp.py:157] [basehttp:log_message] [INFO]- "GET /static/rest_framework/css/prettify.css HTTP/1.1" 200 817
[2021-01-06 18:50:24,159] [basehttp.py:157] [basehttp:log_message] [INFO]- "GET /static/rest_framework/js/ajax-form.js HTTP/1.1" 200 3597
[2021-01-06 18:50:24,163] [basehttp.py:157] [basehttp:log_message] [INFO]- "GET /static/rest_framework/css/bootstrap.min.css HTTP/1.1" 200 121457
[2021-01-06 18:50:24,165] [basehttp.py:157] [basehttp:log_message] [INFO]- "GET /static/rest_framework/js/jquery-3.5.1.min.js HTTP/1.1" 200 89476
[2021-01-06 18:50:24,166] [basehttp.py:157] [basehttp:log_message] [INFO]- "GET /static/rest_framework/js/csrf.js HTTP/1.1" 200 1719
[2021-01-06 18:50:24,174] [basehttp.py:157] [basehttp:log_message] [INFO]- "GET /static/rest_framework/js/default.js HTTP/1.1" 200 1268
[2021-01-06 18:50:24,174] [basehttp.py:157] [basehttp:log_message] [INFO]- "GET /static/rest_framework/js/prettify-min.js HTTP/1.1" 200 13632
[2021-01-06 18:50:24,175] [basehttp.py:157] [basehttp:log_message] [INFO]- "GET /static/rest_framework/js/bootstrap.min.js HTTP/1.1" 200 39680
[2021-01-06 18:50:24,207] [basehttp.py:157] [basehttp:log_message] [INFO]- "GET /static/rest_framework/img/grid.png HTTP/1.1" 200 1458
[2021-01-06 18:50:27,477] [basehttp.py:157] [basehttp:log_message] [INFO]- "GET /user/ HTTP/1.1" 200 16084
[2021-01-06 18:50:32,870] [basehttp.py:157] [basehttp:log_message] [INFO]- "GET / HTTP/1.1" 200 5256
[2021-01-06 18:51:29,189] [autoreload.py:240] [autoreload:trigger_reload] [INFO]- E:\Python\blog\backend\user\urls.py changed, reloading.
[2021-01-06 18:51:29,860] [autoreload.py:617] [autoreload:run_with_reloader] [INFO]- Watching for file changes with StatReloader
[2021-01-06 18:51:51,364] [autoreload.py:617] [autoreload:run_with_reloader] [INFO]- Watching for file changes with StatReloader
[2021-01-06 18:51:54,467] [basehttp.py:157] [basehttp:log_message] [INFO]- "GET / HTTP/1.1" 200 5256
[2021-01-06 18:52:01,978] [basehttp.py:157] [basehttp:log_message] [INFO]- "GET /user/user HTTP/1.1" 200 16071
[2021-01-06 18:52:25,392] [log.py:224] [log:log_response] [WARNING]- Bad Request: /user/user
[2021-01-06 18:52:25,392] [basehttp.py:157] [basehttp:log_message] [WARNING]- "POST /user/user HTTP/1.1" 400 119
[2021-01-06 18:53:12,075] [log.py:224] [log:log_response] [ERROR]- Internal Server Error: /user/user
Traceback (most recent call last):
  File "C:\Users\13155\AppData\Local\Programs\Python\Python39\lib\site-packages\django\core\handlers\exception.py", line 47, in inner
    response = get_response(request)
  File "C:\Users\13155\AppData\Local\Programs\Python\Python39\lib\site-packages\django\core\handlers\base.py", line 179, in _get_response
    response = wrapped_callback(request, *callback_args, **callback_kwargs)
  File "C:\Users\13155\AppData\Local\Programs\Python\Python39\lib\site-packages\django\views\decorators\csrf.py", line 54, in wrapped_view
    return view_func(*args, **kwargs)
  File "C:\Users\13155\AppData\Local\Programs\Python\Python39\lib\site-packages\rest_framework\viewsets.py", line 125, in view
    return self.dispatch(request, *args, **kwargs)
  File "C:\Users\13155\AppData\Local\Programs\Python\Python39\lib\site-packages\rest_framework\views.py", line 509, in dispatch
    response = self.handle_exception(exc)
  File "C:\Users\13155\AppData\Local\Programs\Python\Python39\lib\site-packages\rest_framework\views.py", line 469, in handle_exception
    self.raise_uncaught_exception(exc)
  File "C:\Users\13155\AppData\Local\Programs\Python\Python39\lib\site-packages\rest_framework\views.py", line 480, in raise_uncaught_exception
    raise exc
  File "C:\Users\13155\AppData\Local\Programs\Python\Python39\lib\site-packages\rest_framework\views.py", line 506, in dispatch
    response = handler(request, *args, **kwargs)
  File "C:\Users\13155\AppData\Local\Programs\Python\Python39\lib\site-packages\rest_framework\mixins.py", line 19, in create
    self.perform_create(serializer)
  File "C:\Users\13155\AppData\Local\Programs\Python\Python39\lib\site-packages\rest_framework\mixins.py", line 24, in perform_create
    serializer.save()
  File "C:\Users\13155\AppData\Local\Programs\Python\Python39\lib\site-packages\rest_framework\serializers.py", line 206, in save
    assert self.instance is not None, (
AssertionError: `create()` did not return an object instance.
[2021-01-06 18:53:12,078] [basehttp.py:157] [basehttp:log_message] [ERROR]- "POST /user/user HTTP/1.1" 500 111446
[2021-01-06 18:53:22,551] [log.py:224] [log:log_response] [WARNING]- Bad Request: /user/user
[2021-01-06 18:53:22,552] [basehttp.py:157] [basehttp:log_message] [WARNING]- "POST /user/user HTTP/1.1" 400 59
[2021-01-06 18:54:44,063] [basehttp.py:157] [basehttp:log_message] [INFO]- "GET /user/ HTTP/1.1" 200 16771
[2021-01-06 18:55:55,320] [autoreload.py:240] [autoreload:trigger_reload] [INFO]- E:\Python\blog\backend\user\serializers.py changed, reloading.
[2021-01-06 18:55:56,007] [autoreload.py:617] [autoreload:run_with_reloader] [INFO]- Watching for file changes with StatReloader
[2021-01-06 18:57:11,699] [autoreload.py:240] [autoreload:trigger_reload] [INFO]- E:\Python\blog\backend\user\serializers.py changed, reloading.
[2021-01-06 18:57:12,471] [autoreload.py:617] [autoreload:run_with_reloader] [INFO]- Watching for file changes with StatReloader
[2021-01-06 19:00:30,368] [autoreload.py:240] [autoreload:trigger_reload] [INFO]- E:\Python\blog\backend\user\serializers.py changed, reloading.
[2021-01-06 19:00:31,032] [autoreload.py:617] [autoreload:run_with_reloader] [INFO]- Watching for file changes with StatReloader
[2021-01-06 19:01:59,948] [autoreload.py:617] [autoreload:run_with_reloader] [INFO]- Watching for file changes with StatReloader
[2021-01-06 19:02:04,010] [log.py:224] [log:log_response] [WARNING]- Bad Request: /user/user
[2021-01-06 19:02:04,011] [basehttp.py:157] [basehttp:log_message] [WARNING]- "POST /user/user HTTP/1.1" 400 59
[2021-01-06 19:02:30,873] [log.py:224] [log:log_response] [ERROR]- Internal Server Error: /user/user
Traceback (most recent call last):
  File "C:\Users\13155\AppData\Local\Programs\Python\Python39\lib\site-packages\django\core\handlers\exception.py", line 47, in inner
    response = get_response(request)
  File "C:\Users\13155\AppData\Local\Programs\Python\Python39\lib\site-packages\django\core\handlers\base.py", line 179, in _get_response
    response = wrapped_callback(request, *callback_args, **callback_kwargs)
  File "C:\Users\13155\AppData\Local\Programs\Python\Python39\lib\site-packages\django\views\decorators\csrf.py", line 54, in wrapped_view
    return view_func(*args, **kwargs)
  File "C:\Users\13155\AppData\Local\Programs\Python\Python39\lib\site-packages\rest_framework\viewsets.py", line 125, in view
    return self.dispatch(request, *args, **kwargs)
  File "C:\Users\13155\AppData\Local\Programs\Python\Python39\lib\site-packages\rest_framework\views.py", line 509, in dispatch
    response = self.handle_exception(exc)
  File "C:\Users\13155\AppData\Local\Programs\Python\Python39\lib\site-packages\rest_framework\views.py", line 469, in handle_exception
    self.raise_uncaught_exception(exc)
  File "C:\Users\13155\AppData\Local\Programs\Python\Python39\lib\site-packages\rest_framework\views.py", line 480, in raise_uncaught_exception
    raise exc
  File "C:\Users\13155\AppData\Local\Programs\Python\Python39\lib\site-packages\rest_framework\views.py", line 506, in dispatch
    response = handler(request, *args, **kwargs)
  File "C:\Users\13155\AppData\Local\Programs\Python\Python39\lib\site-packages\rest_framework\mixins.py", line 19, in create
    self.perform_create(serializer)
  File "C:\Users\13155\AppData\Local\Programs\Python\Python39\lib\site-packages\rest_framework\mixins.py", line 24, in perform_create
    serializer.save()
  File "C:\Users\13155\AppData\Local\Programs\Python\Python39\lib\site-packages\rest_framework\serializers.py", line 206, in save
    assert self.instance is not None, (
AssertionError: `create()` did not return an object instance.
[2021-01-06 19:02:30,875] [basehttp.py:157] [basehttp:log_message] [ERROR]- "POST /user/user HTTP/1.1" 500 111486
[2021-01-06 19:02:36,840] [log.py:224] [log:log_response] [WARNING]- Bad Request: /user/user
[2021-01-06 19:02:36,841] [basehttp.py:157] [basehttp:log_message] [WARNING]- "POST /user/user HTTP/1.1" 400 113
[2021-01-06 19:03:28,604] [autoreload.py:617] [autoreload:run_with_reloader] [INFO]- Watching for file changes with StatReloader
[2021-01-06 19:03:40,017] [log.py:224] [log:log_response] [WARNING]- Bad Request: /user/user
[2021-01-06 19:03:40,017] [basehttp.py:157] [basehttp:log_message] [WARNING]- "POST /user/user HTTP/1.1" 400 55
[2021-01-06 19:03:44,333] [log.py:224] [log:log_response] [ERROR]- Internal Server Error: /user/user
Traceback (most recent call last):
  File "C:\Users\13155\AppData\Local\Programs\Python\Python39\lib\site-packages\rest_framework\fields.py", line 457, in get_attribute
    return get_attribute(instance, self.source_attrs)
  File "C:\Users\13155\AppData\Local\Programs\Python\Python39\lib\site-packages\rest_framework\fields.py", line 97, in get_attribute
    instance = getattr(instance, attr)
AttributeError: 'Response' object has no attribute 'password'

During handling of the above exception, another exception occurred:

Traceback (most recent call last):
  File "C:\Users\13155\AppData\Local\Programs\Python\Python39\lib\site-packages\django\core\handlers\exception.py", line 47, in inner
    response = get_response(request)
  File "C:\Users\13155\AppData\Local\Programs\Python\Python39\lib\site-packages\django\core\handlers\base.py", line 179, in _get_response
    response = wrapped_callback(request, *callback_args, **callback_kwargs)
  File "C:\Users\13155\AppData\Local\Programs\Python\Python39\lib\site-packages\django\views\decorators\csrf.py", line 54, in wrapped_view
    return view_func(*args, **kwargs)
  File "C:\Users\13155\AppData\Local\Programs\Python\Python39\lib\site-packages\rest_framework\viewsets.py", line 125, in view
    return self.dispatch(request, *args, **kwargs)
  File "C:\Users\13155\AppData\Local\Programs\Python\Python39\lib\site-packages\rest_framework\views.py", line 509, in dispatch
    response = self.handle_exception(exc)
  File "C:\Users\13155\AppData\Local\Programs\Python\Python39\lib\site-packages\rest_framework\views.py", line 469, in handle_exception
    self.raise_uncaught_exception(exc)
  File "C:\Users\13155\AppData\Local\Programs\Python\Python39\lib\site-packages\rest_framework\views.py", line 480, in raise_uncaught_exception
    raise exc
  File "C:\Users\13155\AppData\Local\Programs\Python\Python39\lib\site-packages\rest_framework\views.py", line 506, in dispatch
    response = handler(request, *args, **kwargs)
  File "C:\Users\13155\AppData\Local\Programs\Python\Python39\lib\site-packages\rest_framework\mixins.py", line 20, in create
    headers = self.get_success_headers(serializer.data)
  File "C:\Users\13155\AppData\Local\Programs\Python\Python39\lib\site-packages\rest_framework\serializers.py", line 548, in data
    ret = super().data
  File "C:\Users\13155\AppData\Local\Programs\Python\Python39\lib\site-packages\rest_framework\serializers.py", line 246, in data
    self._data = self.to_representation(self.instance)
  File "C:\Users\13155\AppData\Local\Programs\Python\Python39\lib\site-packages\rest_framework\serializers.py", line 502, in to_representation
    attribute = field.get_attribute(instance)
  File "C:\Users\13155\AppData\Local\Programs\Python\Python39\lib\site-packages\rest_framework\fields.py", line 490, in get_attribute
    raise type(exc)(msg)
AttributeError: Got AttributeError when attempting to get a value for field `password` on serializer `UserSerializer`.
The serializer field might be named incorrectly and not match any attribute or key on the `Response` instance.
Original exception text was: 'Response' object has no attribute 'password'.
[2021-01-06 19:03:44,336] [basehttp.py:157] [basehttp:log_message] [ERROR]- "POST /user/user HTTP/1.1" 500 132862
[2021-01-06 19:04:04,287] [autoreload.py:617] [autoreload:run_with_reloader] [INFO]- Watching for file changes with StatReloader
[2021-01-06 19:04:10,062] [log.py:224] [log:log_response] [ERROR]- Internal Server Error: /user/user
Traceback (most recent call last):
  File "C:\Users\13155\AppData\Local\Programs\Python\Python39\lib\site-packages\rest_framework\fields.py", line 457, in get_attribute
    return get_attribute(instance, self.source_attrs)
  File "C:\Users\13155\AppData\Local\Programs\Python\Python39\lib\site-packages\rest_framework\fields.py", line 97, in get_attribute
    instance = getattr(instance, attr)
AttributeError: 'Response' object has no attribute 'password'

During handling of the above exception, another exception occurred:

Traceback (most recent call last):
  File "C:\Users\13155\AppData\Local\Programs\Python\Python39\lib\site-packages\django\core\handlers\exception.py", line 47, in inner
    response = get_response(request)
  File "C:\Users\13155\AppData\Local\Programs\Python\Python39\lib\site-packages\django\core\handlers\base.py", line 179, in _get_response
    response = wrapped_callback(request, *callback_args, **callback_kwargs)
  File "C:\Users\13155\AppData\Local\Programs\Python\Python39\lib\site-packages\django\views\decorators\csrf.py", line 54, in wrapped_view
    return view_func(*args, **kwargs)
  File "C:\Users\13155\AppData\Local\Programs\Python\Python39\lib\site-packages\rest_framework\viewsets.py", line 125, in view
    return self.dispatch(request, *args, **kwargs)
  File "C:\Users\13155\AppData\Local\Programs\Python\Python39\lib\site-packages\rest_framework\views.py", line 509, in dispatch
    response = self.handle_exception(exc)
  File "C:\Users\13155\AppData\Local\Programs\Python\Python39\lib\site-packages\rest_framework\views.py", line 469, in handle_exception
    self.raise_uncaught_exception(exc)
  File "C:\Users\13155\AppData\Local\Programs\Python\Python39\lib\site-packages\rest_framework\views.py", line 480, in raise_uncaught_exception
    raise exc
  File "C:\Users\13155\AppData\Local\Programs\Python\Python39\lib\site-packages\rest_framework\views.py", line 506, in dispatch
    response = handler(request, *args, **kwargs)
  File "C:\Users\13155\AppData\Local\Programs\Python\Python39\lib\site-packages\rest_framework\mixins.py", line 20, in create
    headers = self.get_success_headers(serializer.data)
  File "C:\Users\13155\AppData\Local\Programs\Python\Python39\lib\site-packages\rest_framework\serializers.py", line 548, in data
    ret = super().data
  File "C:\Users\13155\AppData\Local\Programs\Python\Python39\lib\site-packages\rest_framework\serializers.py", line 246, in data
    self._data = self.to_representation(self.instance)
  File "C:\Users\13155\AppData\Local\Programs\Python\Python39\lib\site-packages\rest_framework\serializers.py", line 502, in to_representation
    attribute = field.get_attribute(instance)
  File "C:\Users\13155\AppData\Local\Programs\Python\Python39\lib\site-packages\rest_framework\fields.py", line 490, in get_attribute
    raise type(exc)(msg)
AttributeError: Got AttributeError when attempting to get a value for field `password` on serializer `UserSerializer`.
The serializer field might be named incorrectly and not match any attribute or key on the `Response` instance.
Original exception text was: 'Response' object has no attribute 'password'.
[2021-01-06 19:04:10,066] [basehttp.py:157] [basehttp:log_message] [ERROR]- "POST /user/user HTTP/1.1" 500 132842
[2021-01-06 19:04:43,880] [autoreload.py:617] [autoreload:run_with_reloader] [INFO]- Watching for file changes with StatReloader
[2021-01-06 19:04:50,531] [log.py:224] [log:log_response] [ERROR]- Internal Server Error: /user/user
Traceback (most recent call last):
  File "C:\Users\13155\AppData\Local\Programs\Python\Python39\lib\site-packages\rest_framework\fields.py", line 457, in get_attribute
    return get_attribute(instance, self.source_attrs)
  File "C:\Users\13155\AppData\Local\Programs\Python\Python39\lib\site-packages\rest_framework\fields.py", line 97, in get_attribute
    instance = getattr(instance, attr)
AttributeError: 'Response' object has no attribute 'password'

During handling of the above exception, another exception occurred:

Traceback (most recent call last):
  File "C:\Users\13155\AppData\Local\Programs\Python\Python39\lib\site-packages\django\core\handlers\exception.py", line 47, in inner
    response = get_response(request)
  File "C:\Users\13155\AppData\Local\Programs\Python\Python39\lib\site-packages\django\core\handlers\base.py", line 179, in _get_response
    response = wrapped_callback(request, *callback_args, **callback_kwargs)
  File "C:\Users\13155\AppData\Local\Programs\Python\Python39\lib\site-packages\django\views\decorators\csrf.py", line 54, in wrapped_view
    return view_func(*args, **kwargs)
  File "C:\Users\13155\AppData\Local\Programs\Python\Python39\lib\site-packages\rest_framework\viewsets.py", line 125, in view
    return self.dispatch(request, *args, **kwargs)
  File "C:\Users\13155\AppData\Local\Programs\Python\Python39\lib\site-packages\rest_framework\views.py", line 509, in dispatch
    response = self.handle_exception(exc)
  File "C:\Users\13155\AppData\Local\Programs\Python\Python39\lib\site-packages\rest_framework\views.py", line 469, in handle_exception
    self.raise_uncaught_exception(exc)
  File "C:\Users\13155\AppData\Local\Programs\Python\Python39\lib\site-packages\rest_framework\views.py", line 480, in raise_uncaught_exception
    raise exc
  File "C:\Users\13155\AppData\Local\Programs\Python\Python39\lib\site-packages\rest_framework\views.py", line 506, in dispatch
    response = handler(request, *args, **kwargs)
  File "C:\Users\13155\AppData\Local\Programs\Python\Python39\lib\site-packages\rest_framework\mixins.py", line 20, in create
    headers = self.get_success_headers(serializer.data)
  File "C:\Users\13155\AppData\Local\Programs\Python\Python39\lib\site-packages\rest_framework\serializers.py", line 548, in data
    ret = super().data
  File "C:\Users\13155\AppData\Local\Programs\Python\Python39\lib\site-packages\rest_framework\serializers.py", line 246, in data
    self._data = self.to_representation(self.instance)
  File "C:\Users\13155\AppData\Local\Programs\Python\Python39\lib\site-packages\rest_framework\serializers.py", line 502, in to_representation
    attribute = field.get_attribute(instance)
  File "C:\Users\13155\AppData\Local\Programs\Python\Python39\lib\site-packages\rest_framework\fields.py", line 490, in get_attribute
    raise type(exc)(msg)
AttributeError: Got AttributeError when attempting to get a value for field `password` on serializer `UserSerializer`.
The serializer field might be named incorrectly and not match any attribute or key on the `Response` instance.
Original exception text was: 'Response' object has no attribute 'password'.
[2021-01-06 19:04:50,534] [basehttp.py:157] [basehttp:log_message] [ERROR]- "POST /user/user HTTP/1.1" 500 132822
[2021-01-06 19:05:30,594] [autoreload.py:617] [autoreload:run_with_reloader] [INFO]- Watching for file changes with StatReloader
[2021-01-06 19:05:40,588] [log.py:224] [log:log_response] [ERROR]- Internal Server Error: /user/user
Traceback (most recent call last):
  File "C:\Users\13155\AppData\Local\Programs\Python\Python39\lib\site-packages\rest_framework\fields.py", line 457, in get_attribute
    return get_attribute(instance, self.source_attrs)
  File "C:\Users\13155\AppData\Local\Programs\Python\Python39\lib\site-packages\rest_framework\fields.py", line 97, in get_attribute
    instance = getattr(instance, attr)
AttributeError: 'Response' object has no attribute 'password'

During handling of the above exception, another exception occurred:

Traceback (most recent call last):
  File "C:\Users\13155\AppData\Local\Programs\Python\Python39\lib\site-packages\django\core\handlers\exception.py", line 47, in inner
    response = get_response(request)
  File "C:\Users\13155\AppData\Local\Programs\Python\Python39\lib\site-packages\django\core\handlers\base.py", line 179, in _get_response
    response = wrapped_callback(request, *callback_args, **callback_kwargs)
  File "C:\Users\13155\AppData\Local\Programs\Python\Python39\lib\site-packages\django\views\decorators\csrf.py", line 54, in wrapped_view
    return view_func(*args, **kwargs)
  File "C:\Users\13155\AppData\Local\Programs\Python\Python39\lib\site-packages\rest_framework\viewsets.py", line 125, in view
    return self.dispatch(request, *args, **kwargs)
  File "C:\Users\13155\AppData\Local\Programs\Python\Python39\lib\site-packages\rest_framework\views.py", line 509, in dispatch
    response = self.handle_exception(exc)
  File "C:\Users\13155\AppData\Local\Programs\Python\Python39\lib\site-packages\rest_framework\views.py", line 469, in handle_exception
    self.raise_uncaught_exception(exc)
  File "C:\Users\13155\AppData\Local\Programs\Python\Python39\lib\site-packages\rest_framework\views.py", line 480, in raise_uncaught_exception
    raise exc
  File "C:\Users\13155\AppData\Local\Programs\Python\Python39\lib\site-packages\rest_framework\views.py", line 506, in dispatch
    response = handler(request, *args, **kwargs)
  File "C:\Users\13155\AppData\Local\Programs\Python\Python39\lib\site-packages\rest_framework\mixins.py", line 20, in create
    headers = self.get_success_headers(serializer.data)
  File "C:\Users\13155\AppData\Local\Programs\Python\Python39\lib\site-packages\rest_framework\serializers.py", line 548, in data
    ret = super().data
  File "C:\Users\13155\AppData\Local\Programs\Python\Python39\lib\site-packages\rest_framework\serializers.py", line 246, in data
    self._data = self.to_representation(self.instance)
  File "C:\Users\13155\AppData\Local\Programs\Python\Python39\lib\site-packages\rest_framework\serializers.py", line 502, in to_representation
    attribute = field.get_attribute(instance)
  File "C:\Users\13155\AppData\Local\Programs\Python\Python39\lib\site-packages\rest_framework\fields.py", line 490, in get_attribute
    raise type(exc)(msg)
AttributeError: Got AttributeError when attempting to get a value for field `password` on serializer `UserSerializer`.
The serializer field might be named incorrectly and not match any attribute or key on the `Response` instance.
Original exception text was: 'Response' object has no attribute 'password'.
[2021-01-06 19:05:40,591] [basehttp.py:157] [basehttp:log_message] [ERROR]- "POST /user/user HTTP/1.1" 500 132827
[2021-01-06 19:06:01,514] [basehttp.py:157] [basehttp:log_message] [INFO]- "GET /user/user HTTP/1.1" 200 19540
[2021-01-06 19:06:11,140] [basehttp.py:157] [basehttp:log_message] [INFO]- "GET /user/user HTTP/1.1" 200 19540
[2021-01-06 19:06:15,522] [log.py:224] [log:log_response] [ERROR]- Internal Server Error: /user/user
Traceback (most recent call last):
  File "C:\Users\13155\AppData\Local\Programs\Python\Python39\lib\site-packages\rest_framework\fields.py", line 457, in get_attribute
    return get_attribute(instance, self.source_attrs)
  File "C:\Users\13155\AppData\Local\Programs\Python\Python39\lib\site-packages\rest_framework\fields.py", line 97, in get_attribute
    instance = getattr(instance, attr)
AttributeError: 'Response' object has no attribute 'password'

During handling of the above exception, another exception occurred:

Traceback (most recent call last):
  File "C:\Users\13155\AppData\Local\Programs\Python\Python39\lib\site-packages\django\core\handlers\exception.py", line 47, in inner
    response = get_response(request)
  File "C:\Users\13155\AppData\Local\Programs\Python\Python39\lib\site-packages\django\core\handlers\base.py", line 179, in _get_response
    response = wrapped_callback(request, *callback_args, **callback_kwargs)
  File "C:\Users\13155\AppData\Local\Programs\Python\Python39\lib\site-packages\django\views\decorators\csrf.py", line 54, in wrapped_view
    return view_func(*args, **kwargs)
  File "C:\Users\13155\AppData\Local\Programs\Python\Python39\lib\site-packages\rest_framework\viewsets.py", line 125, in view
    return self.dispatch(request, *args, **kwargs)
  File "C:\Users\13155\AppData\Local\Programs\Python\Python39\lib\site-packages\rest_framework\views.py", line 509, in dispatch
    response = self.handle_exception(exc)
  File "C:\Users\13155\AppData\Local\Programs\Python\Python39\lib\site-packages\rest_framework\views.py", line 469, in handle_exception
    self.raise_uncaught_exception(exc)
  File "C:\Users\13155\AppData\Local\Programs\Python\Python39\lib\site-packages\rest_framework\views.py", line 480, in raise_uncaught_exception
    raise exc
  File "C:\Users\13155\AppData\Local\Programs\Python\Python39\lib\site-packages\rest_framework\views.py", line 506, in dispatch
    response = handler(request, *args, **kwargs)
  File "C:\Users\13155\AppData\Local\Programs\Python\Python39\lib\site-packages\rest_framework\mixins.py", line 20, in create
    headers = self.get_success_headers(serializer.data)
  File "C:\Users\13155\AppData\Local\Programs\Python\Python39\lib\site-packages\rest_framework\serializers.py", line 548, in data
    ret = super().data
  File "C:\Users\13155\AppData\Local\Programs\Python\Python39\lib\site-packages\rest_framework\serializers.py", line 246, in data
    self._data = self.to_representation(self.instance)
  File "C:\Users\13155\AppData\Local\Programs\Python\Python39\lib\site-packages\rest_framework\serializers.py", line 502, in to_representation
    attribute = field.get_attribute(instance)
  File "C:\Users\13155\AppData\Local\Programs\Python\Python39\lib\site-packages\rest_framework\fields.py", line 490, in get_attribute
    raise type(exc)(msg)
AttributeError: Got AttributeError when attempting to get a value for field `password` on serializer `UserSerializer`.
The serializer field might be named incorrectly and not match any attribute or key on the `Response` instance.
Original exception text was: 'Response' object has no attribute 'password'.
[2021-01-06 19:06:15,523] [basehttp.py:157] [basehttp:log_message] [ERROR]- "POST /user/user HTTP/1.1" 500 132827
[2021-01-06 19:06:20,105] [basehttp.py:157] [basehttp:log_message] [INFO]- "GET /user/user HTTP/1.1" 200 19540
[2021-01-06 19:08:00,852] [autoreload.py:617] [autoreload:run_with_reloader] [INFO]- Watching for file changes with StatReloader
[2021-01-06 19:09:16,223] [log.py:224] [log:log_response] [ERROR]- Internal Server Error: /user/user
Traceback (most recent call last):
  File "C:\Users\13155\AppData\Local\Programs\Python\Python39\lib\site-packages\rest_framework\fields.py", line 457, in get_attribute
    return get_attribute(instance, self.source_attrs)
  File "C:\Users\13155\AppData\Local\Programs\Python\Python39\lib\site-packages\rest_framework\fields.py", line 97, in get_attribute
    instance = getattr(instance, attr)
AttributeError: 'Response' object has no attribute 'password'

During handling of the above exception, another exception occurred:

Traceback (most recent call last):
  File "C:\Users\13155\AppData\Local\Programs\Python\Python39\lib\site-packages\django\core\handlers\exception.py", line 47, in inner
    response = get_response(request)
  File "C:\Users\13155\AppData\Local\Programs\Python\Python39\lib\site-packages\django\core\handlers\base.py", line 179, in _get_response
    response = wrapped_callback(request, *callback_args, **callback_kwargs)
  File "C:\Users\13155\AppData\Local\Programs\Python\Python39\lib\site-packages\django\views\decorators\csrf.py", line 54, in wrapped_view
    return view_func(*args, **kwargs)
  File "C:\Users\13155\AppData\Local\Programs\Python\Python39\lib\site-packages\rest_framework\viewsets.py", line 125, in view
    return self.dispatch(request, *args, **kwargs)
  File "C:\Users\13155\AppData\Local\Programs\Python\Python39\lib\site-packages\rest_framework\views.py", line 509, in dispatch
    response = self.handle_exception(exc)
  File "C:\Users\13155\AppData\Local\Programs\Python\Python39\lib\site-packages\rest_framework\views.py", line 469, in handle_exception
    self.raise_uncaught_exception(exc)
  File "C:\Users\13155\AppData\Local\Programs\Python\Python39\lib\site-packages\rest_framework\views.py", line 480, in raise_uncaught_exception
    raise exc
  File "C:\Users\13155\AppData\Local\Programs\Python\Python39\lib\site-packages\rest_framework\views.py", line 506, in dispatch
    response = handler(request, *args, **kwargs)
  File "C:\Users\13155\AppData\Local\Programs\Python\Python39\lib\site-packages\rest_framework\mixins.py", line 20, in create
    headers = self.get_success_headers(serializer.data)
  File "C:\Users\13155\AppData\Local\Programs\Python\Python39\lib\site-packages\rest_framework\serializers.py", line 548, in data
    ret = super().data
  File "C:\Users\13155\AppData\Local\Programs\Python\Python39\lib\site-packages\rest_framework\serializers.py", line 246, in data
    self._data = self.to_representation(self.instance)
  File "C:\Users\13155\AppData\Local\Programs\Python\Python39\lib\site-packages\rest_framework\serializers.py", line 502, in to_representation
    attribute = field.get_attribute(instance)
  File "C:\Users\13155\AppData\Local\Programs\Python\Python39\lib\site-packages\rest_framework\fields.py", line 490, in get_attribute
    raise type(exc)(msg)
AttributeError: Got AttributeError when attempting to get a value for field `password` on serializer `UserSerializer`.
The serializer field might be named incorrectly and not match any attribute or key on the `Response` instance.
Original exception text was: 'Response' object has no attribute 'password'.
[2021-01-06 19:09:16,229] [basehttp.py:157] [basehttp:log_message] [ERROR]- "POST /user/user HTTP/1.1" 500 135384
[2021-01-06 19:10:49,260] [autoreload.py:617] [autoreload:run_with_reloader] [INFO]- Watching for file changes with StatReloader
[2021-01-06 19:10:52,234] [log.py:224] [log:log_response] [ERROR]- Internal Server Error: /user/user
Traceback (most recent call last):
  File "C:\Users\13155\AppData\Local\Programs\Python\Python39\lib\site-packages\django\core\handlers\exception.py", line 47, in inner
    response = get_response(request)
  File "C:\Users\13155\AppData\Local\Programs\Python\Python39\lib\site-packages\django\core\handlers\base.py", line 179, in _get_response
    response = wrapped_callback(request, *callback_args, **callback_kwargs)
  File "C:\Users\13155\AppData\Local\Programs\Python\Python39\lib\site-packages\django\views\decorators\csrf.py", line 54, in wrapped_view
    return view_func(*args, **kwargs)
  File "C:\Users\13155\AppData\Local\Programs\Python\Python39\lib\site-packages\rest_framework\viewsets.py", line 117, in view
    handler = getattr(self, action)
AttributeError: 'UserViewSet' object has no attribute 'register'
[2021-01-06 19:10:52,236] [basehttp.py:157] [basehttp:log_message] [ERROR]- "POST /user/user HTTP/1.1" 500 73842
[2021-01-06 19:11:00,963] [log.py:224] [log:log_response] [ERROR]- Internal Server Error: /user/user
Traceback (most recent call last):
  File "C:\Users\13155\AppData\Local\Programs\Python\Python39\lib\site-packages\django\core\handlers\exception.py", line 47, in inner
    response = get_response(request)
  File "C:\Users\13155\AppData\Local\Programs\Python\Python39\lib\site-packages\django\core\handlers\base.py", line 179, in _get_response
    response = wrapped_callback(request, *callback_args, **callback_kwargs)
  File "C:\Users\13155\AppData\Local\Programs\Python\Python39\lib\site-packages\django\views\decorators\csrf.py", line 54, in wrapped_view
    return view_func(*args, **kwargs)
  File "C:\Users\13155\AppData\Local\Programs\Python\Python39\lib\site-packages\rest_framework\viewsets.py", line 117, in view
    handler = getattr(self, action)
AttributeError: 'UserViewSet' object has no attribute 'register'
[2021-01-06 19:11:00,964] [basehttp.py:157] [basehttp:log_message] [ERROR]- "POST /user/user HTTP/1.1" 500 73842
[2021-01-06 19:12:00,437] [autoreload.py:240] [autoreload:trigger_reload] [INFO]- E:\Python\blog\backend\user\urls.py changed, reloading.
[2021-01-06 19:12:01,103] [autoreload.py:617] [autoreload:run_with_reloader] [INFO]- Watching for file changes with StatReloader
[2021-01-06 19:12:01,585] [log.py:224] [log:log_response] [WARNING]- Bad Request: /user/user
[2021-01-06 19:12:01,586] [basehttp.py:157] [basehttp:log_message] [WARNING]- "POST /user/user HTTP/1.1" 400 113
[2021-01-06 19:12:20,712] [log.py:224] [log:log_response] [ERROR]- Internal Server Error: /user/user
Traceback (most recent call last):
  File "C:\Users\13155\AppData\Local\Programs\Python\Python39\lib\site-packages\django\core\handlers\exception.py", line 47, in inner
    response = get_response(request)
  File "C:\Users\13155\AppData\Local\Programs\Python\Python39\lib\site-packages\django\core\handlers\base.py", line 179, in _get_response
    response = wrapped_callback(request, *callback_args, **callback_kwargs)
  File "C:\Users\13155\AppData\Local\Programs\Python\Python39\lib\site-packages\django\views\decorators\csrf.py", line 54, in wrapped_view
    return view_func(*args, **kwargs)
  File "C:\Users\13155\AppData\Local\Programs\Python\Python39\lib\site-packages\rest_framework\viewsets.py", line 125, in view
    return self.dispatch(request, *args, **kwargs)
  File "C:\Users\13155\AppData\Local\Programs\Python\Python39\lib\site-packages\rest_framework\views.py", line 509, in dispatch
    response = self.handle_exception(exc)
  File "C:\Users\13155\AppData\Local\Programs\Python\Python39\lib\site-packages\rest_framework\views.py", line 469, in handle_exception
    self.raise_uncaught_exception(exc)
  File "C:\Users\13155\AppData\Local\Programs\Python\Python39\lib\site-packages\rest_framework\views.py", line 480, in raise_uncaught_exception
    raise exc
  File "C:\Users\13155\AppData\Local\Programs\Python\Python39\lib\site-packages\rest_framework\views.py", line 506, in dispatch
    response = handler(request, *args, **kwargs)
  File "C:\Users\13155\AppData\Local\Programs\Python\Python39\lib\site-packages\rest_framework\mixins.py", line 19, in create
    self.perform_create(serializer)
  File "C:\Users\13155\AppData\Local\Programs\Python\Python39\lib\site-packages\rest_framework\mixins.py", line 24, in perform_create
    serializer.save()
  File "C:\Users\13155\AppData\Local\Programs\Python\Python39\lib\site-packages\rest_framework\serializers.py", line 206, in save
    assert self.instance is not None, (
AssertionError: `create()` did not return an object instance.
[2021-01-06 19:12:20,716] [basehttp.py:157] [basehttp:log_message] [ERROR]- "POST /user/user HTTP/1.1" 500 111491
[2021-01-06 19:12:35,850] [autoreload.py:617] [autoreload:run_with_reloader] [INFO]- Watching for file changes with StatReloader
[2021-01-06 19:12:47,170] [basehttp.py:157] [basehttp:log_message] [INFO]- "POST /user/user HTTP/1.1" 201 356
[2021-01-06 19:13:56,997] [autoreload.py:617] [autoreload:run_with_reloader] [INFO]- Watching for file changes with StatReloader
[2021-01-06 19:14:04,196] [log.py:224] [log:log_response] [ERROR]- Internal Server Error: /user/user
Traceback (most recent call last):
  File "C:\Users\13155\AppData\Local\Programs\Python\Python39\lib\site-packages\rest_framework\fields.py", line 457, in get_attribute
    return get_attribute(instance, self.source_attrs)
  File "C:\Users\13155\AppData\Local\Programs\Python\Python39\lib\site-packages\rest_framework\fields.py", line 95, in get_attribute
    instance = instance[attr]
KeyError: 'password'

During handling of the above exception, another exception occurred:

Traceback (most recent call last):
  File "C:\Users\13155\AppData\Local\Programs\Python\Python39\lib\site-packages\django\core\handlers\exception.py", line 47, in inner
    response = get_response(request)
  File "C:\Users\13155\AppData\Local\Programs\Python\Python39\lib\site-packages\django\core\handlers\base.py", line 179, in _get_response
    response = wrapped_callback(request, *callback_args, **callback_kwargs)
  File "C:\Users\13155\AppData\Local\Programs\Python\Python39\lib\site-packages\django\views\decorators\csrf.py", line 54, in wrapped_view
    return view_func(*args, **kwargs)
  File "C:\Users\13155\AppData\Local\Programs\Python\Python39\lib\site-packages\rest_framework\viewsets.py", line 125, in view
    return self.dispatch(request, *args, **kwargs)
  File "C:\Users\13155\AppData\Local\Programs\Python\Python39\lib\site-packages\rest_framework\views.py", line 509, in dispatch
    response = self.handle_exception(exc)
  File "C:\Users\13155\AppData\Local\Programs\Python\Python39\lib\site-packages\rest_framework\views.py", line 469, in handle_exception
    self.raise_uncaught_exception(exc)
  File "C:\Users\13155\AppData\Local\Programs\Python\Python39\lib\site-packages\rest_framework\views.py", line 480, in raise_uncaught_exception
    raise exc
  File "C:\Users\13155\AppData\Local\Programs\Python\Python39\lib\site-packages\rest_framework\views.py", line 506, in dispatch
    response = handler(request, *args, **kwargs)
  File "C:\Users\13155\AppData\Local\Programs\Python\Python39\lib\site-packages\rest_framework\mixins.py", line 20, in create
    headers = self.get_success_headers(serializer.data)
  File "C:\Users\13155\AppData\Local\Programs\Python\Python39\lib\site-packages\rest_framework\serializers.py", line 548, in data
    ret = super().data
  File "C:\Users\13155\AppData\Local\Programs\Python\Python39\lib\site-packages\rest_framework\serializers.py", line 246, in data
    self._data = self.to_representation(self.instance)
  File "C:\Users\13155\AppData\Local\Programs\Python\Python39\lib\site-packages\rest_framework\serializers.py", line 502, in to_representation
    attribute = field.get_attribute(instance)
  File "C:\Users\13155\AppData\Local\Programs\Python\Python39\lib\site-packages\rest_framework\fields.py", line 490, in get_attribute
    raise type(exc)(msg)
KeyError: "Got KeyError when attempting to get a value for field `password` on serializer `UserSerializer`.\nThe serializer field might be named incorrectly and not match any attribute or key on the `dict` instance.\nOriginal exception text was: 'password'."
[2021-01-06 19:14:04,200] [basehttp.py:157] [basehttp:log_message] [ERROR]- "POST /user/user HTTP/1.1" 500 132271
[2021-01-06 19:14:08,978] [log.py:224] [log:log_response] [ERROR]- Internal Server Error: /user/user
Traceback (most recent call last):
  File "C:\Users\13155\AppData\Local\Programs\Python\Python39\lib\site-packages\rest_framework\fields.py", line 457, in get_attribute
    return get_attribute(instance, self.source_attrs)
  File "C:\Users\13155\AppData\Local\Programs\Python\Python39\lib\site-packages\rest_framework\fields.py", line 95, in get_attribute
    instance = instance[attr]
KeyError: 'password'

During handling of the above exception, another exception occurred:

Traceback (most recent call last):
  File "C:\Users\13155\AppData\Local\Programs\Python\Python39\lib\site-packages\django\core\handlers\exception.py", line 47, in inner
    response = get_response(request)
  File "C:\Users\13155\AppData\Local\Programs\Python\Python39\lib\site-packages\django\core\handlers\base.py", line 179, in _get_response
    response = wrapped_callback(request, *callback_args, **callback_kwargs)
  File "C:\Users\13155\AppData\Local\Programs\Python\Python39\lib\site-packages\django\views\decorators\csrf.py", line 54, in wrapped_view
    return view_func(*args, **kwargs)
  File "C:\Users\13155\AppData\Local\Programs\Python\Python39\lib\site-packages\rest_framework\viewsets.py", line 125, in view
    return self.dispatch(request, *args, **kwargs)
  File "C:\Users\13155\AppData\Local\Programs\Python\Python39\lib\site-packages\rest_framework\views.py", line 509, in dispatch
    response = self.handle_exception(exc)
  File "C:\Users\13155\AppData\Local\Programs\Python\Python39\lib\site-packages\rest_framework\views.py", line 469, in handle_exception
    self.raise_uncaught_exception(exc)
  File "C:\Users\13155\AppData\Local\Programs\Python\Python39\lib\site-packages\rest_framework\views.py", line 480, in raise_uncaught_exception
    raise exc
  File "C:\Users\13155\AppData\Local\Programs\Python\Python39\lib\site-packages\rest_framework\views.py", line 506, in dispatch
    response = handler(request, *args, **kwargs)
  File "C:\Users\13155\AppData\Local\Programs\Python\Python39\lib\site-packages\rest_framework\mixins.py", line 20, in create
    headers = self.get_success_headers(serializer.data)
  File "C:\Users\13155\AppData\Local\Programs\Python\Python39\lib\site-packages\rest_framework\serializers.py", line 548, in data
    ret = super().data
  File "C:\Users\13155\AppData\Local\Programs\Python\Python39\lib\site-packages\rest_framework\serializers.py", line 246, in data
    self._data = self.to_representation(self.instance)
  File "C:\Users\13155\AppData\Local\Programs\Python\Python39\lib\site-packages\rest_framework\serializers.py", line 502, in to_representation
    attribute = field.get_attribute(instance)
  File "C:\Users\13155\AppData\Local\Programs\Python\Python39\lib\site-packages\rest_framework\fields.py", line 490, in get_attribute
    raise type(exc)(msg)
KeyError: "Got KeyError when attempting to get a value for field `password` on serializer `UserSerializer`.\nThe serializer field might be named incorrectly and not match any attribute or key on the `dict` instance.\nOriginal exception text was: 'password'."
[2021-01-06 19:14:08,980] [basehttp.py:157] [basehttp:log_message] [ERROR]- "POST /user/user HTTP/1.1" 500 132271
[2021-01-06 19:14:24,725] [autoreload.py:240] [autoreload:trigger_reload] [INFO]- E:\Python\blog\backend\user\serializers.py changed, reloading.
[2021-01-06 19:14:25,447] [autoreload.py:617] [autoreload:run_with_reloader] [INFO]- Watching for file changes with StatReloader
[2021-01-06 19:14:26,297] [basehttp.py:157] [basehttp:log_message] [INFO]- "POST /user/user HTTP/1.1" 201 353
[2021-01-06 19:19:14,531] [autoreload.py:617] [autoreload:run_with_reloader] [INFO]- Watching for file changes with StatReloader
[2021-01-06 19:19:17,560] [log.py:224] [log:log_response] [WARNING]- Bad Request: /user/user
[2021-01-06 19:19:17,560] [basehttp.py:157] [basehttp:log_message] [WARNING]- "POST /user/user HTTP/1.1" 400 113
[2021-01-06 19:19:25,159] [log.py:224] [log:log_response] [ERROR]- Internal Server Error: /user/user
Traceback (most recent call last):
  File "C:\Users\13155\AppData\Local\Programs\Python\Python39\lib\site-packages\rest_framework\fields.py", line 457, in get_attribute
    return get_attribute(instance, self.source_attrs)
  File "C:\Users\13155\AppData\Local\Programs\Python\Python39\lib\site-packages\rest_framework\fields.py", line 97, in get_attribute
    instance = getattr(instance, attr)
AttributeError: 'JsonResponse' object has no attribute 'password'

During handling of the above exception, another exception occurred:

Traceback (most recent call last):
  File "C:\Users\13155\AppData\Local\Programs\Python\Python39\lib\site-packages\django\core\handlers\exception.py", line 47, in inner
    response = get_response(request)
  File "C:\Users\13155\AppData\Local\Programs\Python\Python39\lib\site-packages\django\core\handlers\base.py", line 179, in _get_response
    response = wrapped_callback(request, *callback_args, **callback_kwargs)
  File "C:\Users\13155\AppData\Local\Programs\Python\Python39\lib\site-packages\django\views\decorators\csrf.py", line 54, in wrapped_view
    return view_func(*args, **kwargs)
  File "C:\Users\13155\AppData\Local\Programs\Python\Python39\lib\site-packages\rest_framework\viewsets.py", line 125, in view
    return self.dispatch(request, *args, **kwargs)
  File "C:\Users\13155\AppData\Local\Programs\Python\Python39\lib\site-packages\rest_framework\views.py", line 509, in dispatch
    response = self.handle_exception(exc)
  File "C:\Users\13155\AppData\Local\Programs\Python\Python39\lib\site-packages\rest_framework\views.py", line 469, in handle_exception
    self.raise_uncaught_exception(exc)
  File "C:\Users\13155\AppData\Local\Programs\Python\Python39\lib\site-packages\rest_framework\views.py", line 480, in raise_uncaught_exception
    raise exc
  File "C:\Users\13155\AppData\Local\Programs\Python\Python39\lib\site-packages\rest_framework\views.py", line 506, in dispatch
    response = handler(request, *args, **kwargs)
  File "C:\Users\13155\AppData\Local\Programs\Python\Python39\lib\site-packages\rest_framework\mixins.py", line 20, in create
    headers = self.get_success_headers(serializer.data)
  File "C:\Users\13155\AppData\Local\Programs\Python\Python39\lib\site-packages\rest_framework\serializers.py", line 548, in data
    ret = super().data
  File "C:\Users\13155\AppData\Local\Programs\Python\Python39\lib\site-packages\rest_framework\serializers.py", line 246, in data
    self._data = self.to_representation(self.instance)
  File "C:\Users\13155\AppData\Local\Programs\Python\Python39\lib\site-packages\rest_framework\serializers.py", line 502, in to_representation
    attribute = field.get_attribute(instance)
  File "C:\Users\13155\AppData\Local\Programs\Python\Python39\lib\site-packages\rest_framework\fields.py", line 490, in get_attribute
    raise type(exc)(msg)
AttributeError: Got AttributeError when attempting to get a value for field `password` on serializer `UserSerializer`.
The serializer field might be named incorrectly and not match any attribute or key on the `JsonResponse` instance.
Original exception text was: 'JsonResponse' object has no attribute 'password'.
[2021-01-06 19:19:25,162] [basehttp.py:157] [basehttp:log_message] [ERROR]- "POST /user/user HTTP/1.1" 500 132926
[2021-01-06 19:21:56,869] [autoreload.py:617] [autoreload:run_with_reloader] [INFO]- Watching for file changes with StatReloader
[2021-01-06 19:22:40,683] [autoreload.py:617] [autoreload:run_with_reloader] [INFO]- Watching for file changes with StatReloader
[2021-01-06 19:22:44,419] [basehttp.py:157] [basehttp:log_message] [INFO]- "GET /user/user HTTP/1.1" 200 22413
[2021-01-06 19:27:06,945] [autoreload.py:240] [autoreload:trigger_reload] [INFO]- E:\Python\blog\blog\settings.py changed, reloading.
[2021-01-06 19:27:07,705] [autoreload.py:617] [autoreload:run_with_reloader] [INFO]- Watching for file changes with StatReloader
[2021-01-06 19:28:06,752] [autoreload.py:617] [autoreload:run_with_reloader] [INFO]- Watching for file changes with StatReloader
[2021-01-06 19:29:39,870] [autoreload.py:617] [autoreload:run_with_reloader] [INFO]- Watching for file changes with StatReloader
[2021-01-06 19:29:43,004] [basehttp.py:157] [basehttp:log_message] [INFO]- "GET / HTTP/1.1" 200 5256
[2021-01-06 19:29:45,037] [basehttp.py:157] [basehttp:log_message] [INFO]- "GET /user/ HTTP/1.1" 200 22381
[2021-01-06 19:29:54,809] [basehttp.py:157] [basehttp:log_message] [INFO]- "GET /admin/ HTTP/1.1" 302 0
[2021-01-06 19:29:54,859] [basehttp.py:157] [basehttp:log_message] [INFO]- "GET /admin/login/?next=/admin/ HTTP/1.1" 200 3732
[2021-01-06 19:29:55,711] [basehttp.py:157] [basehttp:log_message] [INFO]- "GET /static/admin/simpleui-x/js/login.js?_=3.3 HTTP/1.1" 200 669
[2021-01-06 19:29:55,712] [basehttp.py:157] [basehttp:log_message] [INFO]- "GET /static/admin/simpleui-x/css/login.css?_=2.1 HTTP/1.1" 200 500
[2021-01-06 19:29:55,712] [basehttp.py:157] [basehttp:log_message] [INFO]- "GET /static/admin/simpleui-x/particles/app.js HTTP/1.1" 200 3728
[2021-01-06 19:29:55,715] [basehttp.py:157] [basehttp:log_message] [INFO]- "GET /static/admin/simpleui-x/img/logo.png HTTP/1.1" 200 115997
[2021-01-06 19:29:55,717] [basehttp.py:157] [basehttp:log_message] [INFO]- "GET /static/admin/simpleui-x/particles/particles.js HTTP/1.1" 200 51264
[2021-01-06 19:29:55,801] [basehttp.py:157] [basehttp:log_message] [INFO]- "GET /static/admin/simpleui-x/img/bg.svg HTTP/1.1" 200 9547
[2021-01-06 19:30:08,353] [basehttp.py:157] [basehttp:log_message] [INFO]- "POST /admin/login/?next=/admin/ HTTP/1.1" 200 3975
[2021-01-06 19:30:28,924] [log.py:224] [log:log_response] [ERROR]- Internal Server Error: /admin/login/
Traceback (most recent call last):
  File "C:\Users\13155\AppData\Local\Programs\Python\Python39\lib\site-packages\django_redis\cache.py", line 27, in _decorator
    return method(self, *args, **kwargs)
  File "C:\Users\13155\AppData\Local\Programs\Python\Python39\lib\site-packages\django_redis\cache.py", line 131, in has_key
    return self.client.has_key(*args, **kwargs)
  File "C:\Users\13155\AppData\Local\Programs\Python\Python39\lib\site-packages\django_redis\client\default.py", line 511, in has_key
    raise ConnectionInterrupted(connection=client) from e
django_redis.exceptions.ConnectionInterrupted: Redis ConnectionError: Error 10061 connecting to 127.0.0.1:6379. 由于目标计算机积极拒绝，无法连接。.

During handling of the above exception, another exception occurred:

Traceback (most recent call last):
  File "C:\Users\13155\AppData\Local\Programs\Python\Python39\lib\site-packages\django\core\handlers\exception.py", line 47, in inner
    response = get_response(request)
  File "C:\Users\13155\AppData\Local\Programs\Python\Python39\lib\site-packages\django\core\handlers\base.py", line 179, in _get_response
    response = wrapped_callback(request, *callback_args, **callback_kwargs)
  File "C:\Users\13155\AppData\Local\Programs\Python\Python39\lib\site-packages\django\views\decorators\cache.py", line 44, in _wrapped_view_func
    response = view_func(request, *args, **kwargs)
  File "C:\Users\13155\AppData\Local\Programs\Python\Python39\lib\site-packages\django\contrib\admin\sites.py", line 410, in login
    return LoginView.as_view(**defaults)(request)
  File "C:\Users\13155\AppData\Local\Programs\Python\Python39\lib\site-packages\django\views\generic\base.py", line 70, in view
    return self.dispatch(request, *args, **kwargs)
  File "C:\Users\13155\AppData\Local\Programs\Python\Python39\lib\site-packages\django\utils\decorators.py", line 43, in _wrapper
    return bound_method(*args, **kwargs)
  File "C:\Users\13155\AppData\Local\Programs\Python\Python39\lib\site-packages\django\views\decorators\debug.py", line 89, in sensitive_post_parameters_wrapper
    return view(request, *args, **kwargs)
  File "C:\Users\13155\AppData\Local\Programs\Python\Python39\lib\site-packages\django\utils\decorators.py", line 43, in _wrapper
    return bound_method(*args, **kwargs)
  File "C:\Users\13155\AppData\Local\Programs\Python\Python39\lib\site-packages\django\utils\decorators.py", line 130, in _wrapped_view
    response = view_func(request, *args, **kwargs)
  File "C:\Users\13155\AppData\Local\Programs\Python\Python39\lib\site-packages\django\utils\decorators.py", line 43, in _wrapper
    return bound_method(*args, **kwargs)
  File "C:\Users\13155\AppData\Local\Programs\Python\Python39\lib\site-packages\django\views\decorators\cache.py", line 44, in _wrapped_view_func
    response = view_func(request, *args, **kwargs)
  File "C:\Users\13155\AppData\Local\Programs\Python\Python39\lib\site-packages\django\contrib\auth\views.py", line 63, in dispatch
    return super().dispatch(request, *args, **kwargs)
  File "C:\Users\13155\AppData\Local\Programs\Python\Python39\lib\site-packages\django\views\generic\base.py", line 98, in dispatch
    return handler(request, *args, **kwargs)
  File "C:\Users\13155\AppData\Local\Programs\Python\Python39\lib\site-packages\django\views\generic\edit.py", line 142, in post
    return self.form_valid(form)
  File "C:\Users\13155\AppData\Local\Programs\Python\Python39\lib\site-packages\django\contrib\auth\views.py", line 92, in form_valid
    auth_login(self.request, form.get_user())
  File "C:\Users\13155\AppData\Local\Programs\Python\Python39\lib\site-packages\django\contrib\auth\__init__.py", line 108, in login
    request.session.cycle_key()
  File "C:\Users\13155\AppData\Local\Programs\Python\Python39\lib\site-packages\django\contrib\sessions\backends\base.py", line 344, in cycle_key
    self.create()
  File "C:\Users\13155\AppData\Local\Programs\Python\Python39\lib\site-packages\django\contrib\sessions\backends\cache.py", line 43, in create
    self._session_key = self._get_new_session_key()
  File "C:\Users\13155\AppData\Local\Programs\Python\Python39\lib\site-packages\django\contrib\sessions\backends\base.py", line 196, in _get_new_session_key
    if not self.exists(session_key):
  File "C:\Users\13155\AppData\Local\Programs\Python\Python39\lib\site-packages\django\contrib\sessions\backends\cache.py", line 70, in exists
    return bool(session_key) and (self.cache_key_prefix + session_key) in self._cache
  File "C:\Users\13155\AppData\Local\Programs\Python\Python39\lib\site-packages\django\core\cache\backends\base.py", line 212, in __contains__
    return self.has_key(key)
  File "C:\Users\13155\AppData\Local\Programs\Python\Python39\lib\site-packages\django_redis\cache.py", line 34, in _decorator
    raise e.__cause__
  File "C:\Users\13155\AppData\Local\Programs\Python\Python39\lib\site-packages\django_redis\client\default.py", line 509, in has_key
    return client.exists(key) == 1
  File "C:\Users\13155\AppData\Local\Programs\Python\Python39\lib\site-packages\redis\client.py", line 1581, in exists
    return self.execute_command('EXISTS', *names)
  File "C:\Users\13155\AppData\Local\Programs\Python\Python39\lib\site-packages\redis\client.py", line 898, in execute_command
    conn = self.connection or pool.get_connection(command_name, **options)
  File "C:\Users\13155\AppData\Local\Programs\Python\Python39\lib\site-packages\redis\connection.py", line 1192, in get_connection
    connection.connect()
  File "C:\Users\13155\AppData\Local\Programs\Python\Python39\lib\site-packages\redis\connection.py", line 563, in connect
    raise ConnectionError(self._error_message(e))
redis.exceptions.ConnectionError: Error 10061 connecting to 127.0.0.1:6379. 由于目标计算机积极拒绝，无法连接。.
[2021-01-06 19:30:28,933] [basehttp.py:157] [basehttp:log_message] [ERROR]- "POST /admin/login/?next=/admin/ HTTP/1.1" 500 192286
[2021-01-06 19:31:10,732] [log.py:224] [log:log_response] [ERROR]- Internal Server Error: /admin/login/
Traceback (most recent call last):
  File "C:\Users\13155\AppData\Local\Programs\Python\Python39\lib\site-packages\django_redis\cache.py", line 27, in _decorator
    return method(self, *args, **kwargs)
  File "C:\Users\13155\AppData\Local\Programs\Python\Python39\lib\site-packages\django_redis\cache.py", line 131, in has_key
    return self.client.has_key(*args, **kwargs)
  File "C:\Users\13155\AppData\Local\Programs\Python\Python39\lib\site-packages\django_redis\client\default.py", line 511, in has_key
    raise ConnectionInterrupted(connection=client) from e
django_redis.exceptions.ConnectionInterrupted: Redis ConnectionError: Error 10061 connecting to 127.0.0.1:6379. 由于目标计算机积极拒绝，无法连接。.

During handling of the above exception, another exception occurred:

Traceback (most recent call last):
  File "C:\Users\13155\AppData\Local\Programs\Python\Python39\lib\site-packages\django\core\handlers\exception.py", line 47, in inner
    response = get_response(request)
  File "C:\Users\13155\AppData\Local\Programs\Python\Python39\lib\site-packages\django\core\handlers\base.py", line 179, in _get_response
    response = wrapped_callback(request, *callback_args, **callback_kwargs)
  File "C:\Users\13155\AppData\Local\Programs\Python\Python39\lib\site-packages\django\views\decorators\cache.py", line 44, in _wrapped_view_func
    response = view_func(request, *args, **kwargs)
  File "C:\Users\13155\AppData\Local\Programs\Python\Python39\lib\site-packages\django\contrib\admin\sites.py", line 410, in login
    return LoginView.as_view(**defaults)(request)
  File "C:\Users\13155\AppData\Local\Programs\Python\Python39\lib\site-packages\django\views\generic\base.py", line 70, in view
    return self.dispatch(request, *args, **kwargs)
  File "C:\Users\13155\AppData\Local\Programs\Python\Python39\lib\site-packages\django\utils\decorators.py", line 43, in _wrapper
    return bound_method(*args, **kwargs)
  File "C:\Users\13155\AppData\Local\Programs\Python\Python39\lib\site-packages\django\views\decorators\debug.py", line 89, in sensitive_post_parameters_wrapper
    return view(request, *args, **kwargs)
  File "C:\Users\13155\AppData\Local\Programs\Python\Python39\lib\site-packages\django\utils\decorators.py", line 43, in _wrapper
    return bound_method(*args, **kwargs)
  File "C:\Users\13155\AppData\Local\Programs\Python\Python39\lib\site-packages\django\utils\decorators.py", line 130, in _wrapped_view
    response = view_func(request, *args, **kwargs)
  File "C:\Users\13155\AppData\Local\Programs\Python\Python39\lib\site-packages\django\utils\decorators.py", line 43, in _wrapper
    return bound_method(*args, **kwargs)
  File "C:\Users\13155\AppData\Local\Programs\Python\Python39\lib\site-packages\django\views\decorators\cache.py", line 44, in _wrapped_view_func
    response = view_func(request, *args, **kwargs)
  File "C:\Users\13155\AppData\Local\Programs\Python\Python39\lib\site-packages\django\contrib\auth\views.py", line 63, in dispatch
    return super().dispatch(request, *args, **kwargs)
  File "C:\Users\13155\AppData\Local\Programs\Python\Python39\lib\site-packages\django\views\generic\base.py", line 98, in dispatch
    return handler(request, *args, **kwargs)
  File "C:\Users\13155\AppData\Local\Programs\Python\Python39\lib\site-packages\django\views\generic\edit.py", line 142, in post
    return self.form_valid(form)
  File "C:\Users\13155\AppData\Local\Programs\Python\Python39\lib\site-packages\django\contrib\auth\views.py", line 92, in form_valid
    auth_login(self.request, form.get_user())
  File "C:\Users\13155\AppData\Local\Programs\Python\Python39\lib\site-packages\django\contrib\auth\__init__.py", line 108, in login
    request.session.cycle_key()
  File "C:\Users\13155\AppData\Local\Programs\Python\Python39\lib\site-packages\django\contrib\sessions\backends\base.py", line 344, in cycle_key
    self.create()
  File "C:\Users\13155\AppData\Local\Programs\Python\Python39\lib\site-packages\django\contrib\sessions\backends\cache.py", line 43, in create
    self._session_key = self._get_new_session_key()
  File "C:\Users\13155\AppData\Local\Programs\Python\Python39\lib\site-packages\django\contrib\sessions\backends\base.py", line 196, in _get_new_session_key
    if not self.exists(session_key):
  File "C:\Users\13155\AppData\Local\Programs\Python\Python39\lib\site-packages\django\contrib\sessions\backends\cache.py", line 70, in exists
    return bool(session_key) and (self.cache_key_prefix + session_key) in self._cache
  File "C:\Users\13155\AppData\Local\Programs\Python\Python39\lib\site-packages\django\core\cache\backends\base.py", line 212, in __contains__
    return self.has_key(key)
  File "C:\Users\13155\AppData\Local\Programs\Python\Python39\lib\site-packages\django_redis\cache.py", line 34, in _decorator
    raise e.__cause__
  File "C:\Users\13155\AppData\Local\Programs\Python\Python39\lib\site-packages\django_redis\client\default.py", line 509, in has_key
    return client.exists(key) == 1
  File "C:\Users\13155\AppData\Local\Programs\Python\Python39\lib\site-packages\redis\client.py", line 1581, in exists
    return self.execute_command('EXISTS', *names)
  File "C:\Users\13155\AppData\Local\Programs\Python\Python39\lib\site-packages\redis\client.py", line 898, in execute_command
    conn = self.connection or pool.get_connection(command_name, **options)
  File "C:\Users\13155\AppData\Local\Programs\Python\Python39\lib\site-packages\redis\connection.py", line 1192, in get_connection
    connection.connect()
  File "C:\Users\13155\AppData\Local\Programs\Python\Python39\lib\site-packages\redis\connection.py", line 563, in connect
    raise ConnectionError(self._error_message(e))
redis.exceptions.ConnectionError: Error 10061 connecting to 127.0.0.1:6379. 由于目标计算机积极拒绝，无法连接。.
[2021-01-06 19:31:13,201] [basehttp.py:157] [basehttp:log_message] [INFO]- "GET /admin/login/?next=/admin/ HTTP/1.1" 200 3732
[2021-01-06 19:31:27,790] [log.py:224] [log:log_response] [ERROR]- Internal Server Error: /admin/login/
Traceback (most recent call last):
  File "C:\Users\13155\AppData\Local\Programs\Python\Python39\lib\site-packages\django_redis\cache.py", line 27, in _decorator
    return method(self, *args, **kwargs)
  File "C:\Users\13155\AppData\Local\Programs\Python\Python39\lib\site-packages\django_redis\cache.py", line 131, in has_key
    return self.client.has_key(*args, **kwargs)
  File "C:\Users\13155\AppData\Local\Programs\Python\Python39\lib\site-packages\django_redis\client\default.py", line 511, in has_key
    raise ConnectionInterrupted(connection=client) from e
django_redis.exceptions.ConnectionInterrupted: Redis ConnectionError: Error 10061 connecting to 127.0.0.1:6379. 由于目标计算机积极拒绝，无法连接。.

During handling of the above exception, another exception occurred:

Traceback (most recent call last):
  File "C:\Users\13155\AppData\Local\Programs\Python\Python39\lib\site-packages\django\core\handlers\exception.py", line 47, in inner
    response = get_response(request)
  File "C:\Users\13155\AppData\Local\Programs\Python\Python39\lib\site-packages\django\core\handlers\base.py", line 179, in _get_response
    response = wrapped_callback(request, *callback_args, **callback_kwargs)
  File "C:\Users\13155\AppData\Local\Programs\Python\Python39\lib\site-packages\django\views\decorators\cache.py", line 44, in _wrapped_view_func
    response = view_func(request, *args, **kwargs)
  File "C:\Users\13155\AppData\Local\Programs\Python\Python39\lib\site-packages\django\contrib\admin\sites.py", line 410, in login
    return LoginView.as_view(**defaults)(request)
  File "C:\Users\13155\AppData\Local\Programs\Python\Python39\lib\site-packages\django\views\generic\base.py", line 70, in view
    return self.dispatch(request, *args, **kwargs)
  File "C:\Users\13155\AppData\Local\Programs\Python\Python39\lib\site-packages\django\utils\decorators.py", line 43, in _wrapper
    return bound_method(*args, **kwargs)
  File "C:\Users\13155\AppData\Local\Programs\Python\Python39\lib\site-packages\django\views\decorators\debug.py", line 89, in sensitive_post_parameters_wrapper
    return view(request, *args, **kwargs)
  File "C:\Users\13155\AppData\Local\Programs\Python\Python39\lib\site-packages\django\utils\decorators.py", line 43, in _wrapper
    return bound_method(*args, **kwargs)
  File "C:\Users\13155\AppData\Local\Programs\Python\Python39\lib\site-packages\django\utils\decorators.py", line 130, in _wrapped_view
    response = view_func(request, *args, **kwargs)
  File "C:\Users\13155\AppData\Local\Programs\Python\Python39\lib\site-packages\django\utils\decorators.py", line 43, in _wrapper
    return bound_method(*args, **kwargs)
  File "C:\Users\13155\AppData\Local\Programs\Python\Python39\lib\site-packages\django\views\decorators\cache.py", line 44, in _wrapped_view_func
    response = view_func(request, *args, **kwargs)
  File "C:\Users\13155\AppData\Local\Programs\Python\Python39\lib\site-packages\django\contrib\auth\views.py", line 63, in dispatch
    return super().dispatch(request, *args, **kwargs)
  File "C:\Users\13155\AppData\Local\Programs\Python\Python39\lib\site-packages\django\views\generic\base.py", line 98, in dispatch
    return handler(request, *args, **kwargs)
  File "C:\Users\13155\AppData\Local\Programs\Python\Python39\lib\site-packages\django\views\generic\edit.py", line 142, in post
    return self.form_valid(form)
  File "C:\Users\13155\AppData\Local\Programs\Python\Python39\lib\site-packages\django\contrib\auth\views.py", line 92, in form_valid
    auth_login(self.request, form.get_user())
  File "C:\Users\13155\AppData\Local\Programs\Python\Python39\lib\site-packages\django\contrib\auth\__init__.py", line 108, in login
    request.session.cycle_key()
  File "C:\Users\13155\AppData\Local\Programs\Python\Python39\lib\site-packages\django\contrib\sessions\backends\base.py", line 344, in cycle_key
    self.create()
  File "C:\Users\13155\AppData\Local\Programs\Python\Python39\lib\site-packages\django\contrib\sessions\backends\cache.py", line 43, in create
    self._session_key = self._get_new_session_key()
  File "C:\Users\13155\AppData\Local\Programs\Python\Python39\lib\site-packages\django\contrib\sessions\backends\base.py", line 196, in _get_new_session_key
    if not self.exists(session_key):
  File "C:\Users\13155\AppData\Local\Programs\Python\Python39\lib\site-packages\django\contrib\sessions\backends\cache.py", line 70, in exists
    return bool(session_key) and (self.cache_key_prefix + session_key) in self._cache
  File "C:\Users\13155\AppData\Local\Programs\Python\Python39\lib\site-packages\django\core\cache\backends\base.py", line 212, in __contains__
    return self.has_key(key)
  File "C:\Users\13155\AppData\Local\Programs\Python\Python39\lib\site-packages\django_redis\cache.py", line 34, in _decorator
    raise e.__cause__
  File "C:\Users\13155\AppData\Local\Programs\Python\Python39\lib\site-packages\django_redis\client\default.py", line 509, in has_key
    return client.exists(key) == 1
  File "C:\Users\13155\AppData\Local\Programs\Python\Python39\lib\site-packages\redis\client.py", line 1581, in exists
    return self.execute_command('EXISTS', *names)
  File "C:\Users\13155\AppData\Local\Programs\Python\Python39\lib\site-packages\redis\client.py", line 898, in execute_command
    conn = self.connection or pool.get_connection(command_name, **options)
  File "C:\Users\13155\AppData\Local\Programs\Python\Python39\lib\site-packages\redis\connection.py", line 1192, in get_connection
    connection.connect()
  File "C:\Users\13155\AppData\Local\Programs\Python\Python39\lib\site-packages\redis\connection.py", line 563, in connect
    raise ConnectionError(self._error_message(e))
redis.exceptions.ConnectionError: Error 10061 connecting to 127.0.0.1:6379. 由于目标计算机积极拒绝，无法连接。.
[2021-01-06 19:31:27,800] [basehttp.py:157] [basehttp:log_message] [ERROR]- "POST /admin/login/?next=/admin/ HTTP/1.1" 500 192286
[2021-01-06 19:31:59,910] [autoreload.py:240] [autoreload:trigger_reload] [INFO]- E:\Python\blog\backend\user\admin.py changed, reloading.
[2021-01-06 19:32:00,675] [autoreload.py:617] [autoreload:run_with_reloader] [INFO]- Watching for file changes with StatReloader
[2021-01-06 19:32:47,701] [autoreload.py:240] [autoreload:trigger_reload] [INFO]- E:\Python\blog\backend\user\admin.py changed, reloading.
[2021-01-06 19:32:48,414] [autoreload.py:617] [autoreload:run_with_reloader] [INFO]- Watching for file changes with StatReloader
[2021-01-06 19:32:55,525] [log.py:224] [log:log_response] [ERROR]- Internal Server Error: /admin/login/
Traceback (most recent call last):
  File "C:\Users\13155\AppData\Local\Programs\Python\Python39\lib\site-packages\django_redis\cache.py", line 27, in _decorator
    return method(self, *args, **kwargs)
  File "C:\Users\13155\AppData\Local\Programs\Python\Python39\lib\site-packages\django_redis\cache.py", line 131, in has_key
    return self.client.has_key(*args, **kwargs)
  File "C:\Users\13155\AppData\Local\Programs\Python\Python39\lib\site-packages\django_redis\client\default.py", line 511, in has_key
    raise ConnectionInterrupted(connection=client) from e
django_redis.exceptions.ConnectionInterrupted: Redis ConnectionError: Error 10061 connecting to 127.0.0.1:6379. 由于目标计算机积极拒绝，无法连接。.

During handling of the above exception, another exception occurred:

Traceback (most recent call last):
  File "C:\Users\13155\AppData\Local\Programs\Python\Python39\lib\site-packages\django\core\handlers\exception.py", line 47, in inner
    response = get_response(request)
  File "C:\Users\13155\AppData\Local\Programs\Python\Python39\lib\site-packages\django\core\handlers\base.py", line 179, in _get_response
    response = wrapped_callback(request, *callback_args, **callback_kwargs)
  File "C:\Users\13155\AppData\Local\Programs\Python\Python39\lib\site-packages\django\views\decorators\cache.py", line 44, in _wrapped_view_func
    response = view_func(request, *args, **kwargs)
  File "C:\Users\13155\AppData\Local\Programs\Python\Python39\lib\site-packages\django\contrib\admin\sites.py", line 410, in login
    return LoginView.as_view(**defaults)(request)
  File "C:\Users\13155\AppData\Local\Programs\Python\Python39\lib\site-packages\django\views\generic\base.py", line 70, in view
    return self.dispatch(request, *args, **kwargs)
  File "C:\Users\13155\AppData\Local\Programs\Python\Python39\lib\site-packages\django\utils\decorators.py", line 43, in _wrapper
    return bound_method(*args, **kwargs)
  File "C:\Users\13155\AppData\Local\Programs\Python\Python39\lib\site-packages\django\views\decorators\debug.py", line 89, in sensitive_post_parameters_wrapper
    return view(request, *args, **kwargs)
  File "C:\Users\13155\AppData\Local\Programs\Python\Python39\lib\site-packages\django\utils\decorators.py", line 43, in _wrapper
    return bound_method(*args, **kwargs)
  File "C:\Users\13155\AppData\Local\Programs\Python\Python39\lib\site-packages\django\utils\decorators.py", line 130, in _wrapped_view
    response = view_func(request, *args, **kwargs)
  File "C:\Users\13155\AppData\Local\Programs\Python\Python39\lib\site-packages\django\utils\decorators.py", line 43, in _wrapper
    return bound_method(*args, **kwargs)
  File "C:\Users\13155\AppData\Local\Programs\Python\Python39\lib\site-packages\django\views\decorators\cache.py", line 44, in _wrapped_view_func
    response = view_func(request, *args, **kwargs)
  File "C:\Users\13155\AppData\Local\Programs\Python\Python39\lib\site-packages\django\contrib\auth\views.py", line 63, in dispatch
    return super().dispatch(request, *args, **kwargs)
  File "C:\Users\13155\AppData\Local\Programs\Python\Python39\lib\site-packages\django\views\generic\base.py", line 98, in dispatch
    return handler(request, *args, **kwargs)
  File "C:\Users\13155\AppData\Local\Programs\Python\Python39\lib\site-packages\django\views\generic\edit.py", line 142, in post
    return self.form_valid(form)
  File "C:\Users\13155\AppData\Local\Programs\Python\Python39\lib\site-packages\django\contrib\auth\views.py", line 92, in form_valid
    auth_login(self.request, form.get_user())
  File "C:\Users\13155\AppData\Local\Programs\Python\Python39\lib\site-packages\django\contrib\auth\__init__.py", line 108, in login
    request.session.cycle_key()
  File "C:\Users\13155\AppData\Local\Programs\Python\Python39\lib\site-packages\django\contrib\sessions\backends\base.py", line 344, in cycle_key
    self.create()
  File "C:\Users\13155\AppData\Local\Programs\Python\Python39\lib\site-packages\django\contrib\sessions\backends\cache.py", line 43, in create
    self._session_key = self._get_new_session_key()
  File "C:\Users\13155\AppData\Local\Programs\Python\Python39\lib\site-packages\django\contrib\sessions\backends\base.py", line 196, in _get_new_session_key
    if not self.exists(session_key):
  File "C:\Users\13155\AppData\Local\Programs\Python\Python39\lib\site-packages\django\contrib\sessions\backends\cache.py", line 70, in exists
    return bool(session_key) and (self.cache_key_prefix + session_key) in self._cache
  File "C:\Users\13155\AppData\Local\Programs\Python\Python39\lib\site-packages\django\core\cache\backends\base.py", line 212, in __contains__
    return self.has_key(key)
  File "C:\Users\13155\AppData\Local\Programs\Python\Python39\lib\site-packages\django_redis\cache.py", line 34, in _decorator
    raise e.__cause__
  File "C:\Users\13155\AppData\Local\Programs\Python\Python39\lib\site-packages\django_redis\client\default.py", line 509, in has_key
    return client.exists(key) == 1
  File "C:\Users\13155\AppData\Local\Programs\Python\Python39\lib\site-packages\redis\client.py", line 1581, in exists
    return self.execute_command('EXISTS', *names)
  File "C:\Users\13155\AppData\Local\Programs\Python\Python39\lib\site-packages\redis\client.py", line 898, in execute_command
    conn = self.connection or pool.get_connection(command_name, **options)
  File "C:\Users\13155\AppData\Local\Programs\Python\Python39\lib\site-packages\redis\connection.py", line 1192, in get_connection
    connection.connect()
  File "C:\Users\13155\AppData\Local\Programs\Python\Python39\lib\site-packages\redis\connection.py", line 563, in connect
    raise ConnectionError(self._error_message(e))
redis.exceptions.ConnectionError: Error 10061 connecting to 127.0.0.1:6379. 由于目标计算机积极拒绝，无法连接。.
[2021-01-06 19:32:55,533] [basehttp.py:157] [basehttp:log_message] [ERROR]- "POST /admin/login/?next=/admin/ HTTP/1.1" 500 192286
[2021-01-06 19:33:02,374] [autoreload.py:617] [autoreload:run_with_reloader] [INFO]- Watching for file changes with StatReloader
[2021-01-06 19:33:05,549] [basehttp.py:157] [basehttp:log_message] [INFO]- "GET /admin/login/?next=/admin/ HTTP/1.1" 200 3732
[2021-01-06 19:33:20,100] [log.py:224] [log:log_response] [ERROR]- Internal Server Error: /admin/login/
Traceback (most recent call last):
  File "C:\Users\13155\AppData\Local\Programs\Python\Python39\lib\site-packages\django_redis\cache.py", line 27, in _decorator
    return method(self, *args, **kwargs)
  File "C:\Users\13155\AppData\Local\Programs\Python\Python39\lib\site-packages\django_redis\cache.py", line 131, in has_key
    return self.client.has_key(*args, **kwargs)
  File "C:\Users\13155\AppData\Local\Programs\Python\Python39\lib\site-packages\django_redis\client\default.py", line 511, in has_key
    raise ConnectionInterrupted(connection=client) from e
django_redis.exceptions.ConnectionInterrupted: Redis ConnectionError: Error 10061 connecting to 127.0.0.1:6379. 由于目标计算机积极拒绝，无法连接。.

During handling of the above exception, another exception occurred:

Traceback (most recent call last):
  File "C:\Users\13155\AppData\Local\Programs\Python\Python39\lib\site-packages\django\core\handlers\exception.py", line 47, in inner
    response = get_response(request)
  File "C:\Users\13155\AppData\Local\Programs\Python\Python39\lib\site-packages\django\core\handlers\base.py", line 179, in _get_response
    response = wrapped_callback(request, *callback_args, **callback_kwargs)
  File "C:\Users\13155\AppData\Local\Programs\Python\Python39\lib\site-packages\django\views\decorators\cache.py", line 44, in _wrapped_view_func
    response = view_func(request, *args, **kwargs)
  File "C:\Users\13155\AppData\Local\Programs\Python\Python39\lib\site-packages\django\contrib\admin\sites.py", line 410, in login
    return LoginView.as_view(**defaults)(request)
  File "C:\Users\13155\AppData\Local\Programs\Python\Python39\lib\site-packages\django\views\generic\base.py", line 70, in view
    return self.dispatch(request, *args, **kwargs)
  File "C:\Users\13155\AppData\Local\Programs\Python\Python39\lib\site-packages\django\utils\decorators.py", line 43, in _wrapper
    return bound_method(*args, **kwargs)
  File "C:\Users\13155\AppData\Local\Programs\Python\Python39\lib\site-packages\django\views\decorators\debug.py", line 89, in sensitive_post_parameters_wrapper
    return view(request, *args, **kwargs)
  File "C:\Users\13155\AppData\Local\Programs\Python\Python39\lib\site-packages\django\utils\decorators.py", line 43, in _wrapper
    return bound_method(*args, **kwargs)
  File "C:\Users\13155\AppData\Local\Programs\Python\Python39\lib\site-packages\django\utils\decorators.py", line 130, in _wrapped_view
    response = view_func(request, *args, **kwargs)
  File "C:\Users\13155\AppData\Local\Programs\Python\Python39\lib\site-packages\django\utils\decorators.py", line 43, in _wrapper
    return bound_method(*args, **kwargs)
  File "C:\Users\13155\AppData\Local\Programs\Python\Python39\lib\site-packages\django\views\decorators\cache.py", line 44, in _wrapped_view_func
    response = view_func(request, *args, **kwargs)
  File "C:\Users\13155\AppData\Local\Programs\Python\Python39\lib\site-packages\django\contrib\auth\views.py", line 63, in dispatch
    return super().dispatch(request, *args, **kwargs)
  File "C:\Users\13155\AppData\Local\Programs\Python\Python39\lib\site-packages\django\views\generic\base.py", line 98, in dispatch
    return handler(request, *args, **kwargs)
  File "C:\Users\13155\AppData\Local\Programs\Python\Python39\lib\site-packages\django\views\generic\edit.py", line 142, in post
    return self.form_valid(form)
  File "C:\Users\13155\AppData\Local\Programs\Python\Python39\lib\site-packages\django\contrib\auth\views.py", line 92, in form_valid
    auth_login(self.request, form.get_user())
  File "C:\Users\13155\AppData\Local\Programs\Python\Python39\lib\site-packages\django\contrib\auth\__init__.py", line 108, in login
    request.session.cycle_key()
  File "C:\Users\13155\AppData\Local\Programs\Python\Python39\lib\site-packages\django\contrib\sessions\backends\base.py", line 344, in cycle_key
    self.create()
  File "C:\Users\13155\AppData\Local\Programs\Python\Python39\lib\site-packages\django\contrib\sessions\backends\cache.py", line 43, in create
    self._session_key = self._get_new_session_key()
  File "C:\Users\13155\AppData\Local\Programs\Python\Python39\lib\site-packages\django\contrib\sessions\backends\base.py", line 196, in _get_new_session_key
    if not self.exists(session_key):
  File "C:\Users\13155\AppData\Local\Programs\Python\Python39\lib\site-packages\django\contrib\sessions\backends\cache.py", line 70, in exists
    return bool(session_key) and (self.cache_key_prefix + session_key) in self._cache
  File "C:\Users\13155\AppData\Local\Programs\Python\Python39\lib\site-packages\django\core\cache\backends\base.py", line 212, in __contains__
    return self.has_key(key)
  File "C:\Users\13155\AppData\Local\Programs\Python\Python39\lib\site-packages\django_redis\cache.py", line 34, in _decorator
    raise e.__cause__
  File "C:\Users\13155\AppData\Local\Programs\Python\Python39\lib\site-packages\django_redis\client\default.py", line 509, in has_key
    return client.exists(key) == 1
  File "C:\Users\13155\AppData\Local\Programs\Python\Python39\lib\site-packages\redis\client.py", line 1581, in exists
    return self.execute_command('EXISTS', *names)
  File "C:\Users\13155\AppData\Local\Programs\Python\Python39\lib\site-packages\redis\client.py", line 898, in execute_command
    conn = self.connection or pool.get_connection(command_name, **options)
  File "C:\Users\13155\AppData\Local\Programs\Python\Python39\lib\site-packages\redis\connection.py", line 1192, in get_connection
    connection.connect()
  File "C:\Users\13155\AppData\Local\Programs\Python\Python39\lib\site-packages\redis\connection.py", line 563, in connect
    raise ConnectionError(self._error_message(e))
redis.exceptions.ConnectionError: Error 10061 connecting to 127.0.0.1:6379. 由于目标计算机积极拒绝，无法连接。.
[2021-01-06 19:33:20,114] [basehttp.py:157] [basehttp:log_message] [ERROR]- "POST /admin/login/?next=/admin/ HTTP/1.1" 500 192286
[2021-01-06 19:33:56,337] [autoreload.py:617] [autoreload:run_with_reloader] [INFO]- Watching for file changes with StatReloader
[2021-01-06 19:34:00,964] [basehttp.py:157] [basehttp:log_message] [INFO]- "POST /admin/login/?next=/admin/ HTTP/1.1" 302 0
[2021-01-06 19:34:01,021] [basehttp.py:157] [basehttp:log_message] [INFO]- "GET /admin/ HTTP/1.1" 200 18504
[2021-01-06 19:34:02,082] [basehttp.py:157] [basehttp:log_message] [INFO]- "GET /static/admin/simpleui-x/waves/waves.min.css?_=2.1 HTTP/1.1" 200 3861
[2021-01-06 19:34:02,082] [basehttp.py:157] [basehttp:log_message] [INFO]- "GET /static/admin/simpleui-x/automatic/segment.js?_=2021.1.1 HTTP/1.1" 200 1186
[2021-01-06 19:34:02,083] [basehttp.py:157] [basehttp:log_message] [INFO]- "GET /static/admin/simpleui-x/locale/en-us.js?_=2021.1.1 HTTP/1.1" 200 811
[2021-01-06 19:34:02,083] [basehttp.py:157] [basehttp:log_message] [INFO]- "GET /static/admin/simpleui-x/locale/zh-hans.js?_=2021.1.1 HTTP/1.1" 200 1254
[2021-01-06 19:34:02,084] [basehttp.py:157] [basehttp:log_message] [INFO]- "GET /static/admin/simpleui-x/css/index.css?_=3.2 HTTP/1.1" 200 7134
[2021-01-06 19:34:02,086] [basehttp.py:157] [basehttp:log_message] [INFO]- "GET /static/admin/simpleui-x/automatic/dicts.js?_=2021.1.1 HTTP/1.1" 200 6190
[2021-01-06 19:34:02,090] [basehttp.py:157] [basehttp:log_message] [INFO]- "GET /static/admin/simpleui-x/js/cookie.js?_=2021.1.1 HTTP/1.1" 200 524
[2021-01-06 19:34:02,091] [basehttp.py:157] [basehttp:log_message] [INFO]- "GET /static/admin/simpleui-x/theme/theme.js?_=2021.1.1 HTTP/1.1" 200 4274
[2021-01-06 19:34:02,092] [basehttp.py:157] [basehttp:log_message] [INFO]- "GET /static/admin/simpleui-x/waves/waves.min.js?_=2021.1.1 HTTP/1.1" 200 6329
[2021-01-06 19:34:02,092] [basehttp.py:157] [basehttp:log_message] [INFO]- "GET /static/admin/simpleui-x/js/index.js?_=2021.1.1 HTTP/1.1" 200 20711
[2021-01-06 19:34:05,463] [basehttp.py:157] [basehttp:log_message] [INFO]- "GET /admin/user/user/ HTTP/1.1" 200 27271
[2021-01-06 19:34:05,503] [basehttp.py:157] [basehttp:log_message] [INFO]- "GET /static/admin/simpleui-x/js/language.js?_=2.1.2 HTTP/1.1" 200 189
[2021-01-06 19:34:05,503] [basehttp.py:157] [basehttp:log_message] [INFO]- "GET /static/admin/simpleui-x/theme/simpleui.css HTTP/1.1" 200 4421
[2021-01-06 19:34:05,503] [basehttp.py:157] [basehttp:log_message] [INFO]- "GET /static/admin/css/base.css?_=2.7 HTTP/1.1" 200 16206
[2021-01-06 19:34:05,504] [basehttp.py:157] [basehttp:log_message] [INFO]- "GET /static/admin/simpleui-x/css/base.css?_=2.7 HTTP/1.1" 200 3205
[2021-01-06 19:34:05,504] [basehttp.py:157] [basehttp:log_message] [INFO]- "GET /static/admin/simpleui-x/locale/en-us.js?_=2.1.2 HTTP/1.1" 200 811
[2021-01-06 19:34:05,504] [basehttp.py:157] [basehttp:log_message] [INFO]- "GET /static/admin/simpleui-x/locale/zh-hans.js HTTP/1.1" 200 1254
[2021-01-06 19:34:05,523] [basehttp.py:157] [basehttp:log_message] [INFO]- "GET /static/admin/simpleui-x/js/cookie.js HTTP/1.1" 200 524
[2021-01-06 19:34:05,523] [basehttp.py:157] [basehttp:log_message] [INFO]- "GET /static/admin/js/jquery.init.js HTTP/1.1" 200 363
[2021-01-06 19:34:05,523] [basehttp.py:157] [basehttp:log_message] [INFO]- "GET /static/admin/css/responsive.css?_=20180905 HTTP/1.1" 200 17867
[2021-01-06 19:34:05,523] [basehttp.py:157] [basehttp:log_message] [INFO]- "GET /static/admin/css/changelists.css?_=20180905 HTTP/1.1" 200 6305
[2021-01-06 19:34:05,530] [basehttp.py:157] [basehttp:log_message] [INFO]- "GET /admin/jsi18n/ HTTP/1.1" 200 7732
[2021-01-06 19:34:05,530] [basehttp.py:157] [basehttp:log_message] [INFO]- "GET /static/admin/js/core.js HTTP/1.1" 200 7127
[2021-01-06 19:34:05,533] [basehttp.py:157] [basehttp:log_message] [INFO]- "GET /static/admin/js/vendor/jquery/jquery.js HTTP/1.1" 200 360615
[2021-01-06 19:34:05,536] [basehttp.py:157] [basehttp:log_message] [INFO]- "GET /static/admin/js/admin/RelatedObjectLookups.js HTTP/1.1" 200 7183
[2021-01-06 19:34:05,537] [basehttp.py:157] [basehttp:log_message] [INFO]- "GET /static/admin/js/actions.js HTTP/1.1" 200 6778
[2021-01-06 19:34:05,537] [basehttp.py:157] [basehttp:log_message] [INFO]- "GET /static/admin/js/urlify.js HTTP/1.1" 200 8733
[2021-01-06 19:34:05,550] [basehttp.py:157] [basehttp:log_message] [INFO]- "GET /static/admin/js/prepopulate.js HTTP/1.1" 200 1544
[2021-01-06 19:34:05,551] [basehttp.py:157] [basehttp:log_message] [INFO]- "GET /static/admin/simpleui-x/automatic/segment.js HTTP/1.1" 200 1186
[2021-01-06 19:34:05,551] [basehttp.py:157] [basehttp:log_message] [INFO]- "GET /static/admin/simpleui-x/automatic/dicts.js HTTP/1.1" 200 6190
[2021-01-06 19:34:05,552] [basehttp.py:157] [basehttp:log_message] [INFO]- "GET /static/admin/simpleui-x/js/axios.min.js HTTP/1.1" 200 14237
[2021-01-06 19:34:05,553] [basehttp.py:157] [basehttp:log_message] [INFO]- "GET /static/admin/js/vendor/jquery/jquery.min.js HTTP/1.1" 200 85659
[2021-01-06 19:34:05,554] [basehttp.py:157] [basehttp:log_message] [INFO]- "GET /static/admin/js/vendor/xregexp/xregexp.js HTTP/1.1" 200 131709
[2021-01-06 19:34:08,110] [basehttp.py:157] [basehttp:log_message] [INFO]- "GET /admin/user/user/10/change/ HTTP/1.1" 200 27149
[2021-01-06 19:34:08,173] [basehttp.py:157] [basehttp:log_message] [INFO]- "GET /static/admin/js/calendar.js HTTP/1.1" 200 7729
[2021-01-06 19:34:08,173] [basehttp.py:157] [basehttp:log_message] [INFO]- "GET /static/admin/css/forms.css HTTP/1.1" 200 8173
[2021-01-06 19:34:08,174] [basehttp.py:157] [basehttp:log_message] [INFO]- "GET /static/admin/js/admin/DateTimeShortcuts.js HTTP/1.1" 200 20454
[2021-01-06 19:34:08,178] [basehttp.py:157] [basehttp:log_message] [INFO]- "GET /admin/jsi18n/ HTTP/1.1" 200 7732
[2021-01-06 19:34:08,207] [basehttp.py:157] [basehttp:log_message] [INFO]- "GET /static/admin/js/change_form.js HTTP/1.1" 200 715
[2021-01-06 19:34:08,207] [basehttp.py:157] [basehttp:log_message] [INFO]- "GET /static/admin/js/prepopulate_init.js HTTP/1.1" 200 497
[2021-01-06 19:34:08,228] [basehttp.py:157] [basehttp:log_message] [INFO]- "GET /static/admin/css/widgets.css HTTP/1.1" 200 10333
[2021-01-06 19:34:08,236] [basehttp.py:157] [basehttp:log_message] [INFO]- "GET /static/admin/img/icon-addlink.svg HTTP/1.1" 200 343
[2021-01-06 19:34:08,352] [basehttp.py:157] [basehttp:log_message] [INFO]- "GET /static/admin/img/icon-calendar.svg HTTP/1.1" 200 1106
[2021-01-06 19:34:08,374] [basehttp.py:157] [basehttp:log_message] [INFO]- "GET /static/admin/img/icon-clock.svg HTTP/1.1" 200 697
[2021-01-06 19:34:27,041] [basehttp.py:157] [basehttp:log_message] [INFO]- "POST /admin/user/user/10/change/ HTTP/1.1" 302 0
[2021-01-06 19:34:27,139] [basehttp.py:157] [basehttp:log_message] [INFO]- "GET /admin/user/user/ HTTP/1.1" 200 27411
[2021-01-06 19:34:27,197] [basehttp.py:157] [basehttp:log_message] [INFO]- "GET /admin/jsi18n/ HTTP/1.1" 200 7732
[2021-01-06 19:34:29,379] [basehttp.py:157] [basehttp:log_message] [INFO]- "GET /admin/user/user/10/change/ HTTP/1.1" 200 27441
[2021-01-06 19:34:29,431] [basehttp.py:157] [basehttp:log_message] [INFO]- "GET /admin/jsi18n/ HTTP/1.1" 200 7732
[2021-01-06 19:34:29,549] [log.py:224] [log:log_response] [WARNING]- Not Found: /avatar/20210106/林允儿.jpg
[2021-01-06 19:34:29,549] [basehttp.py:157] [basehttp:log_message] [WARNING]- "GET /avatar/20210106/%E6%9E%97%E5%85%81%E5%84%BF.jpg HTTP/1.1" 404 3634
[2021-01-06 19:34:35,002] [basehttp.py:157] [basehttp:log_message] [INFO]- "GET /admin/user/user/ HTTP/1.1" 200 27271
[2021-01-06 19:34:35,053] [basehttp.py:157] [basehttp:log_message] [INFO]- "GET /admin/jsi18n/ HTTP/1.1" 200 7732
[2021-01-06 19:34:36,480] [basehttp.py:157] [basehttp:log_message] [INFO]- "GET /admin/user/user/10/change/ HTTP/1.1" 200 27441
[2021-01-06 19:34:36,547] [basehttp.py:157] [basehttp:log_message] [INFO]- "GET /admin/jsi18n/ HTTP/1.1" 200 7732
[2021-01-06 19:34:36,671] [log.py:224] [log:log_response] [WARNING]- Not Found: /avatar/20210106/林允儿.jpg
[2021-01-06 19:34:36,671] [basehttp.py:157] [basehttp:log_message] [WARNING]- "GET /avatar/20210106/%E6%9E%97%E5%85%81%E5%84%BF.jpg HTTP/1.1" 404 3634
[2021-01-06 19:34:39,211] [log.py:224] [log:log_response] [WARNING]- Not Found: /avatar/20210106/林允儿.jpg
[2021-01-06 19:34:39,211] [basehttp.py:157] [basehttp:log_message] [WARNING]- "GET /avatar/20210106/%E6%9E%97%E5%85%81%E5%84%BF.jpg HTTP/1.1" 404 3634
[2021-01-06 19:36:52,059] [autoreload.py:617] [autoreload:run_with_reloader] [INFO]- Watching for file changes with StatReloader
[2021-01-06 19:36:57,164] [basehttp.py:157] [basehttp:log_message] [INFO]- "GET /admin/ HTTP/1.1" 200 19104
[2021-01-06 19:36:57,553] [basehttp.py:157] [basehttp:log_message] [INFO]- "GET /admin/user/user/ HTTP/1.1" 200 27271
[2021-01-06 19:36:57,582] [basehttp.py:157] [basehttp:log_message] [INFO]- "GET /admin/jsi18n/ HTTP/1.1" 200 7732
[2021-01-06 19:36:59,111] [basehttp.py:157] [basehttp:log_message] [INFO]- "GET /admin/user/user/10/change/ HTTP/1.1" 200 27448
[2021-01-06 19:36:59,166] [basehttp.py:157] [basehttp:log_message] [INFO]- "GET /admin/jsi18n/ HTTP/1.1" 200 7732
[2021-01-06 19:36:59,280] [log.py:224] [log:log_response] [WARNING]- Not Found: /avatar/avatar/20210106/林允儿.jpg
[2021-01-06 19:36:59,280] [basehttp.py:157] [basehttp:log_message] [WARNING]- "GET /avatar/avatar/20210106/%E6%9E%97%E5%85%81%E5%84%BF.jpg HTTP/1.1" 404 3655
[2021-01-06 19:37:05,789] [basehttp.py:157] [basehttp:log_message] [INFO]- "POST /admin/user/user/10/change/ HTTP/1.1" 302 0
[2021-01-06 19:37:05,863] [basehttp.py:157] [basehttp:log_message] [INFO]- "GET /admin/user/user/ HTTP/1.1" 200 27411
[2021-01-06 19:37:05,928] [basehttp.py:157] [basehttp:log_message] [INFO]- "GET /admin/jsi18n/ HTTP/1.1" 200 7732
[2021-01-06 19:37:07,671] [basehttp.py:157] [basehttp:log_message] [INFO]- "GET /admin/user/user/10/change/ HTTP/1.1" 200 27448
[2021-01-06 19:37:07,731] [basehttp.py:157] [basehttp:log_message] [INFO]- "GET /admin/jsi18n/ HTTP/1.1" 200 7732
[2021-01-06 19:37:07,815] [log.py:224] [log:log_response] [WARNING]- Not Found: /avatar/avatar/20210106/刘亦菲.jpg
[2021-01-06 19:37:07,815] [basehttp.py:157] [basehttp:log_message] [WARNING]- "GET /avatar/avatar/20210106/%E5%88%98%E4%BA%A6%E8%8F%B2.jpg HTTP/1.1" 404 3655
[2021-01-06 19:37:10,277] [log.py:224] [log:log_response] [WARNING]- Not Found: /avatar/avatar/20210106/刘亦菲.jpg
[2021-01-06 19:37:10,277] [basehttp.py:157] [basehttp:log_message] [WARNING]- "GET /avatar/avatar/20210106/%E5%88%98%E4%BA%A6%E8%8F%B2.jpg HTTP/1.1" 404 3655
[2021-01-06 19:38:34,987] [autoreload.py:240] [autoreload:trigger_reload] [INFO]- E:\Python\blog\backend\user\urls.py changed, reloading.
[2021-01-06 19:38:35,833] [autoreload.py:617] [autoreload:run_with_reloader] [INFO]- Watching for file changes with StatReloader
[2021-01-06 19:39:15,460] [autoreload.py:617] [autoreload:run_with_reloader] [INFO]- Watching for file changes with StatReloader
[2021-01-06 19:39:20,149] [basehttp.py:157] [basehttp:log_message] [INFO]- "GET /admin/ HTTP/1.1" 200 19481
[2021-01-06 19:39:20,525] [basehttp.py:157] [basehttp:log_message] [INFO]- "GET /admin/user/user/ HTTP/1.1" 200 27271
[2021-01-06 19:39:20,568] [basehttp.py:157] [basehttp:log_message] [INFO]- "GET /admin/jsi18n/ HTTP/1.1" 200 7732
[2021-01-06 19:39:21,971] [basehttp.py:157] [basehttp:log_message] [INFO]- "GET /admin/user/user/10/change/ HTTP/1.1" 200 27448
[2021-01-06 19:39:22,025] [basehttp.py:157] [basehttp:log_message] [INFO]- "GET /admin/jsi18n/ HTTP/1.1" 200 7732
[2021-01-06 19:39:22,316] [basehttp.py:157] [basehttp:log_message] [INFO]- "GET /avatar/avatar/20210106/%E5%88%98%E4%BA%A6%E8%8F%B2.jpg HTTP/1.1" 200 18845
[2021-01-06 19:39:25,502] [basehttp.py:157] [basehttp:log_message] [INFO]- "POST /admin/user/user/10/change/ HTTP/1.1" 302 0
[2021-01-06 19:39:25,576] [basehttp.py:157] [basehttp:log_message] [INFO]- "GET /admin/user/user/ HTTP/1.1" 200 27411
[2021-01-06 19:39:25,643] [basehttp.py:157] [basehttp:log_message] [INFO]- "GET /admin/jsi18n/ HTTP/1.1" 200 7732
[2021-01-06 19:39:27,499] [basehttp.py:157] [basehttp:log_message] [INFO]- "GET /admin/user/user/10/change/ HTTP/1.1" 200 27448
[2021-01-06 19:39:27,558] [basehttp.py:157] [basehttp:log_message] [INFO]- "GET /admin/jsi18n/ HTTP/1.1" 200 7732
[2021-01-06 19:39:31,093] [basehttp.py:157] [basehttp:log_message] [INFO]- "GET /admin/user/user/ HTTP/1.1" 200 27271
[2021-01-06 19:39:31,147] [basehttp.py:157] [basehttp:log_message] [INFO]- "GET /admin/jsi18n/ HTTP/1.1" 200 7732
[2021-01-06 19:39:32,401] [basehttp.py:157] [basehttp:log_message] [INFO]- "GET /admin/user/user/10/change/ HTTP/1.1" 200 27448
[2021-01-06 19:39:32,450] [basehttp.py:157] [basehttp:log_message] [INFO]- "GET /admin/jsi18n/ HTTP/1.1" 200 7732
[2021-01-06 19:40:25,276] [autoreload.py:240] [autoreload:trigger_reload] [INFO]- E:\Python\blog\backend\user\models.py changed, reloading.
[2021-01-06 19:40:25,944] [autoreload.py:617] [autoreload:run_with_reloader] [INFO]- Watching for file changes with StatReloader
[2021-01-06 19:41:14,060] [basehttp.py:157] [basehttp:log_message] [INFO]- "POST /admin/user/user/10/change/ HTTP/1.1" 302 0
[2021-01-06 19:41:14,138] [basehttp.py:157] [basehttp:log_message] [INFO]- "GET /admin/user/user/ HTTP/1.1" 200 27411
[2021-01-06 19:41:14,204] [basehttp.py:157] [basehttp:log_message] [INFO]- "GET /admin/jsi18n/ HTTP/1.1" 200 7732
[2021-01-06 19:41:15,876] [basehttp.py:157] [basehttp:log_message] [INFO]- "GET /admin/user/user/10/change/ HTTP/1.1" 200 27450
[2021-01-06 19:41:15,939] [basehttp.py:157] [basehttp:log_message] [INFO]- "GET /admin/jsi18n/ HTTP/1.1" 200 7732
[2021-01-06 19:41:16,249] [basehttp.py:157] [basehttp:log_message] [INFO]- "GET /avatar/20210106/%E6%9E%97%E5%85%81%E5%84%BF_hpY1DoO.jpg HTTP/1.1" 200 41428
[2021-01-06 19:41:52,432] [basehttp.py:157] [basehttp:log_message] [INFO]- "GET /user/user HTTP/1.1" 200 22675
[2021-01-06 19:42:13,521] [basehttp.py:157] [basehttp:log_message] [INFO]- "GET /avatar/20210106/%E6%9E%97%E5%85%81%E5%84%BF_hpY1DoO.jpg HTTP/1.1" 304 0
[2021-01-06 19:42:31,700] [basehttp.py:157] [basehttp:log_message] [INFO]- "GET /admin/user/user/ HTTP/1.1" 200 27271
[2021-01-06 19:42:31,738] [basehttp.py:157] [basehttp:log_message] [INFO]- "GET /admin/jsi18n/ HTTP/1.1" 200 7732
[2021-01-06 19:43:25,808] [autoreload.py:240] [autoreload:trigger_reload] [INFO]- E:\Python\blog\backend\user\models.py changed, reloading.
[2021-01-06 19:43:26,479] [autoreload.py:617] [autoreload:run_with_reloader] [INFO]- Watching for file changes with StatReloader
[2021-01-06 19:43:37,322] [basehttp.py:157] [basehttp:log_message] [INFO]- "GET /admin/ HTTP/1.1" 200 20241
[2021-01-06 19:43:37,607] [basehttp.py:157] [basehttp:log_message] [INFO]- "GET /admin/user/user/ HTTP/1.1" 200 27271
[2021-01-06 19:43:37,647] [basehttp.py:157] [basehttp:log_message] [INFO]- "GET /admin/jsi18n/ HTTP/1.1" 200 7732
[2021-01-06 19:43:45,040] [autoreload.py:240] [autoreload:trigger_reload] [INFO]- E:\Python\blog\backend\user\models.py changed, reloading.
[2021-01-06 19:43:45,702] [autoreload.py:617] [autoreload:run_with_reloader] [INFO]- Watching for file changes with StatReloader
[2021-01-06 19:43:53,710] [basehttp.py:157] [basehttp:log_message] [INFO]- "GET /admin/ HTTP/1.1" 200 20241
[2021-01-06 19:43:54,044] [basehttp.py:157] [basehttp:log_message] [INFO]- "GET /admin/user/user/ HTTP/1.1" 200 27271
[2021-01-06 19:43:54,091] [basehttp.py:157] [basehttp:log_message] [INFO]- "GET /admin/jsi18n/ HTTP/1.1" 200 7732
